Workbook

Sheet CUEs
B2: =INT(ROW()/56)+1 -> 1 | C2: Q: | D2: ="w1_"&TEXT(B2,"0000") -> w1_0001 | F2: 1 | G2: 2 | H2: 3 | I2: 4 | J2: 5 | K2: 6 | L2: 7 | M2: 8 | N2: 9 | O2: 10 | P2: 11 | Q2: 12 | R2: 13 | S2: 14 | T2: 15 | U2: 16 | V2: 17
B3: Col Off | C3: Gray | D3: DCA #: | F3: ="#D1" -> #D1 | G3: ="#D2" -> #D2 | H3: ="#D3" -> #D3 | I3: ="#D4" -> #D4 | J3: ="#D5" -> #D5 | K3: ="#D6" -> #D6 | L3: ="#D7" -> #D7 | M3: ="#D8" -> #D8 | N3: ="#D9" -> #D9 | O3: ="#D10" -> #D10 | P3: ="#D11" -> #D11 | Q3: ="#D12" -> #D12 | R3: ="#D13" -> #D13 | S3: ="#D14" -> #D14 | T3: ="#D15" -> #D15 | U3: ="#D16" -> #D16 | V3: =""
B4: AMX on | C4: x | D4: Color if On: | F4: Yellow | G4: MediumB | H4: BrightB | I4: Violet | J4: Turquoise | K4: Green | L4: OliveG | M4: Yellow | N4: Brown | O4: Red | P4: Coral | Q4: Pink | R4: DarkV | S4: Gold | T4: LightB | U4: Tangerine | V4: White
B6: AMY on | C6: x | D6: Name: | F6: LEADS | G6: FlotJet | H6: Sail | I6: Sisters | J6: Maids | K6: LeeWind | L6: PrRaJen | M6: . | N6: . | O6: . | P6: OS | Q6: VOX+.VRB | R6: VOX_.VRB | S6: INST+.VRB | T6: INST_.VRB | U6: MAINS | V6: x
F7: =COUNTA(F9:F48) -> 3 | G7: =COUNTA(G9:G48) -> 0 | H7: =COUNTA(H9:H48) -> 0 | I7: =COUNTA(I9:I48) -> 0 | J7: =COUNTA(J9:J48) -> 1 | K7: =COUNTA(K9:K48) -> 1 | L7: =COUNTA(L9:L48) -> 1 | M7: =COUNTA(M9:M48) -> 2 | ... U7: =COUNTA(U9:U48) -> 1 | V7: =40-COUNTBLANK(V9:V48) -> 24
A8: # | B8: AMIxy | C8: OnX | D8: Name | W8: color and tag column | X8: colorname | Y8: color number | Z8: TAG | AA8: usecolor | AB8: COLOR AND MUTE | AC8: TAGS | AD8: NAMES | AE8: POSTINS and Mode | AF8: DCA NAME and COLOR
A9: 1 | B9: x | C9: x | D9: CAROLINE.ariel | E9: =COUNTA(F9:U9) -> 1 | M9: x | V9: =IF(E9=0,"x","") | W9: =_xlfn.XMATCH("x",F9:V9) -> 8 | X9: {=INDEX(F4:V4,W9)} -> Yellow | Y9: =_xlfn.XLOOKUP(X9,refs!$A$2:$A$19,refs!$B$2:$B$19) -> 7 | Z9: {=INDEX($F$3:$V$3,W9)} -> #D8 | AA9: =IF(C9="x",Y9,_xlfn.XLOOKUP(C3,refs!$A$2:$A$19,refs!$B$2:$B$19)) -> 7 | AB9: ="/ch."&A9&".col="&AA9&",mute="&IF(C9="x",0,1)&"," -> /ch.1.col=7,mute=0, | AC9: ="/ch."&A9&".tags="&Z9&"," -> /ch.1.tags=#D8, | AD9: ="/ch."&A9&".name="&LEFT(D9,16)&"," -> /ch.1.name=CAROLINE.ariel, | AE9: ="/ch."&A9&".postins.on="&IF(B9="x",1,IF(B9="y",1,0))&",mode="&IF(B9="x","AUTO_X",IF(B9="y","AUTO_Y","FX"))&"," -> /ch.1.postins.on=1,mode=AUTO_X, | AF9: ="/dca."&F$2&".col="&_xlfn.XLOOKUP(F$4,refs!$A$2:$A$19,refs!$B$2:$B$19)&",name="&LEFT(F$6,16)&"," -> /dca.1.col=7,name=LEADS,
A10: 2 | B10: x | C10: x | D10: GABE.eric | E10: =COUNTA(F10:U10) -> 1 | F10: x | V10: =IF(E10=0,"x","") | W10: =_xlfn.XMATCH("x",F10:V10) -> 1 | X10: {=INDEX(F4:V4,W10)} -> Yellow | Y10: =_xlfn.XLOOKUP(X10,refs!$A$2:$A$19,refs!$B$2:$B$19) -> 7 | Z10: {=INDEX($F$3:$V$3,W10)} -> #D1 | AA10: =IF(C10="x",Y10,_xlfn.XLOOKUP(C3,refs!$A$2:$A$19,refs!$B$2:$B$19)) -> 7 | AB10: ="."&A10&".col="&AA10&",mute="&IF(C10="x",0,1)&"," -> .2.col=7,mute=0, | AC10: ="."&A10&".tags="&Z10&"," -> .2.tags=#D1, | AD10: ="."&A10&".name="&LEFT(D10,166)&"," -> .2.name=GABE.eric, | AE10: =".."&A10&".postins.on="&IF(B10="x",1,IF(B10="y",1,0))&",mode="&IF(B10="x","AUTO_X",IF(B10="y","AUTO_Y","FX"))&"," -> ..2.postins.on=1,mode=AUTO_X, | AF10: ="."&G$2&".col="&_xlfn.XLOOKUP(G$4,refs!$A$2:$A$19,refs!$B$2:$B$19)&",name="&LEFT(G$6,16)&"," -> .2.col=1,name=FlotJet,
A11: 3 | B11: x | C11: x | D11: KEITH.grimsby | E11: =COUNTA(F11:U11) -> 1 | F11: x | V11: =IF(E11=0,"x","") | W11: =_xlfn.XMATCH("x",F11:V11) -> 1 | X11: {=INDEX(F4:V4,W11)} -> Yellow | Y11: =_xlfn.XLOOKUP(X11,refs!$A$2:$A$19,refs!$B$2:$B$19) -> 7 | Z11: {=INDEX($F$3:$V$3,W11)} -> #D1 | AA11: =IF(C11="x",Y11,_xlfn.XLOOKUP(C3,refs!$A$2:$A$19,refs!$B$2:$B$19)) -> 7 | AB11: ="."&A11&".col="&AA11&",mute="&IF(C11="x",0,1)&"," -> .3.col=7,mute=0, | AC11: ="."&A11&".tags="&Z11&"," -> .3.tags=#D1, | AD11: ="."&A11&".name="&LEFT(D11,16)&"," -> .3.name=KEITH.grimsby, | AE11: =".."&A11&".postins.on="&IF(B11="x",1,IF(B11="y",1,0))&",mode="&IF(B11="x","AUTO_X",IF(B11="y","AUTO_Y","FX"))&"," -> ..3.postins.on=1,mode=AUTO_X, | AF11: ="."&H$2&".col="&_xlfn.XLOOKUP(H$4,refs!$A$2:$A$19,refs!$B$2:$B$19)&",name="&LEFT(H$6,16)&"," -> .3.col=2,name=Sail,
A12: 4 | C12: x | D12: CHADLEY.sebastian | E12: =COUNTA(F12:U12) -> 1 | F12: x | V12: =IF(E12=0,"x","") | W12: =_xlfn.XMATCH("x",F12:V12) -> 1 | X12: {=INDEX(F4:V4,W12)} -> Yellow | Y12: =_xlfn.XLOOKUP(X12,refs!$A$2:$A$19,refs!$B$2:$B$19) -> 7 | Z12: {=INDEX($F$3:$V$3,W12)} -> #D1 | AA12: =IF(C12="x",Y12,_xlfn.XLOOKUP(C3,refs!$A$2:$A$19,refs!$B$2:$B$19)) -> 7 | AB12: ="."&A12&".col="&AA12&",mute="&IF(C12="x",0,1)&"," -> .4.col=7,mute=0, | AC12: ="."&A12&".tags="&Z12&"," -> .4.tags=#D1, | AD12: ="."&A12&".name="&LEFT(D12,16)&"," -> .4.name=CHADLEY.sebastia, | AE12: =".."&A12&".postins.on="&IF(B12="x",1,IF(B12="y",1,0))&",mode="&IF(B12="x","AUTO_X",IF(B12="y","AUTO_Y","FX"))&"," -> ..4.postins.on=0,mode=FX, | AF12: ="."&I$2&".col="&_xlfn.XLOOKUP(I$4,refs!$A$2:$A$19,refs!$B$2:$B$19)&",name="&LEFT(I$6,16)&"," -> .4.col=3,name=Sisters,
A13: 5 | B13: x | C13: x | D13: ANNA.flounder | E13: =COUNTA(F13:U13) -> 1 | J13: x | V13: =IF(E13=0,"x","") | W13: =_xlfn.XMATCH("x",F13:V13) -> 5 | X13: {=INDEX(F4:V4,W13)} -> Turquoise | Y13: =_xlfn.XLOOKUP(X13,refs!$A$2:$A$19,refs!$B$2:$B$19) -> 4 | Z13: {=INDEX($F$3:$V$3,W13)} -> #D5 | AA13: =IF(C13="x",Y13,_xlfn.XLOOKUP(C3,refs!$A$2:$A$19,refs!$B$2:$B$19)) -> 4 | AB13: ="."&A13&".col="&AA13&",mute="&IF(C13="x",0,1)&"," -> .5.col=4,mute=0, | AC13: ="."&A13&".tags="&Z13&"," -> .5.tags=#D5, | AD13: ="."&A13&".name="&LEFT(D13,16)&"," -> .5.name=ANNA.flounder, | AE13: =".."&A13&".postins.on="&IF(B13="x",1,IF(B13="y",1,0))&",mode="&IF(B13="x","AUTO_X",IF(B13="y","AUTO_Y","FX"))&"," -> ..5.postins.on=1,mode=AUTO_X, | AF13: ="."&J$2&".col="&_xlfn.XLOOKUP(J$4,refs!$A$2:$A$19,refs!$B$2:$B$19)&",name="&LEFT(J$6,16)&"," -> .5.col=4,name=Maids,
A14: 6 | B14: x | C14: x | D14: MARGERY.ursula | E14: =COUNTA(F14:U14) -> 1 | K14: x | V14: =IF(E14=0,"x","") | W14: =_xlfn.XMATCH("x",F14:V14) -> 6 | X14: {=INDEX(F4:V4,W14)} -> Green | Y14: =_xlfn.XLOOKUP(X14,refs!$A$2:$A$19,refs!$B$2:$B$19) -> 5 | Z14: {=INDEX($F$3:$V$3,W14)} -> #D6 | AA14: =IF(C14="x",Y14,_xlfn.XLOOKUP(C3,refs!$A$2:$A$19,refs!$B$2:$B$19)) -> 5 | AB14: ="."&A14&".col="&AA14&",mute="&IF(C14="x",0,1)&"," -> .6.col=5,mute=0, | AC14: ="."&A14&".tags="&Z14&"," -> .6.tags=#D6, | AD14: ="."&A14&".name="&LEFT(D14,16)&"," -> .6.name=MARGERY.ursula, | AE14: =".."&A14&".postins.on="&IF(B14="x",1,IF(B14="y",1,0))&",mode="&IF(B14="x","AUTO_X",IF(B14="y","AUTO_Y","FX"))&"," -> ..6.postins.on=1,mode=AUTO_X, | AF14: ="."&K$2&".col="&_xlfn.XLOOKUP(K$4,refs!$A$2:$A$19,refs!$B$2:$B$19)&",name="&LEFT(K$6,16)&"," -> .6.col=5,name=LeeWind,
A15: 7 | B15: x | C15: x | D15: JOHN.triton | E15: =COUNTA(F15:U15) -> 1 | L15: x | V15: =IF(E15=0,"x","") | W15: =_xlfn.XMATCH("x",F15:V15) -> 7 | X15: {=INDEX(F4:V4,W15)} -> OliveG | Y15: =_xlfn.XLOOKUP(X15,refs!$A$2:$A$19,refs!$B$2:$B$19) -> 6 | Z15: {=INDEX($F$3:$V$3,W15)} -> #D7 | AA15: =IF(C15="x",Y15,_xlfn.XLOOKUP(C3,refs!$A$2:$A$19,refs!$B$2:$B$19)) -> 6 | AB15: ="."&A15&".col="&AA15&",mute="&IF(C15="x",0,1)&"," -> .7.col=6,mute=0, | AC15: ="."&A15&".tags="&Z15&"," -> .7.tags=#D7, | AD15: ="."&A15&".name="&LEFT(D15,16)&"," -> .7.name=JOHN.triton, | AE15: =".."&A15&".postins.on="&IF(B15="x",1,IF(B15="y",1,0))&",mode="&IF(B15="x","AUTO_X",IF(B15="y","AUTO_Y","FX"))&"," -> ..7.postins.on=1,mode=AUTO_X, | AF15: ="."&L$2&".col="&_xlfn.XLOOKUP(L$4,refs!$A$2:$A$19,refs!$B$2:$B$19)&",name="&LEFT(L$6,16)&"," -> .7.col=6,name=PrRaJen,
A16: 8 | B16: x | C16: x | D16: JUDAH.chefL | E16: =COUNTA(F16:U16) -> 1 | M16: x | V16: =IF(E16=0,"x","") | W16: =_xlfn.XMATCH("x",F16:V16) -> 8 | X16: {=INDEX(F4:V4,W16)} -> Yellow | Y16: =_xlfn.XLOOKUP(X16,refs!$A$2:$A$19,refs!$B$2:$B$19) -> 7 | Z16: {=INDEX($F$3:$V$3,W16)} -> #D8 | AA16: =IF(C16="x",Y16,_xlfn.XLOOKUP(C3,refs!$A$2:$A$19,refs!$B$2:$B$19)) -> 7 | AB16: ="."&A16&".col="&AA16&",mute="&IF(C16="x",0,1)&"," -> .8.col=7,mute=0, | AC16: ="."&A16&".tags="&Z16&"," -> .8.tags=#D8, | AD16: ="."&A16&".name="&LEFT(D16,16)&"," -> .8.name=JUDAH.chefL, | AE16: =".."&A16&".postins.on="&IF(B16="x",1,IF(B16="y",1,0))&",mode="&IF(B16="x","AUTO_X",IF(B16="y","AUTO_Y","FX"))&"," -> ..8.postins.on=1,mode=AUTO_X, | AF16: ="."&M$2&".col="&_xlfn.XLOOKUP(M$4,refs!$A$2:$A$19,refs!$B$2:$B$19)&",name="&LEFT(M$6,16)&"," -> .8.col=7,name=.,
A17: 9 | B17: x | C17: x | D17: BRIDGET.scuttle | E17: =COUNTA(F17:U17) -> 1 | N17: x | V17: =IF(E17=0,"x","") | W17: =_xlfn.XMATCH("x",F17:V17) -> 9 | X17: {=INDEX(F4:V4,W17)} -> Brown | Y17: =_xlfn.XLOOKUP(X17,refs!$A$2:$A$19,refs!$B$2:$B$19) -> 8 | Z17: {=INDEX($F$3:$V$3,W17)} -> #D9 | AA17: =IF(C17="x",Y17,_xlfn.XLOOKUP(C3,refs!$A$2:$A$19,refs!$B$2:$B$19)) -> 8 | AB17: ="."&A17&".col="&AA17&",mute="&IF(C17="x",0,1)&"," -> .9.col=8,mute=0, | AC17: ="."&A17&".tags="&Z17&"," -> .9.tags=#D9, | AD17: ="."&A17&".name="&LEFT(D17,16)&"," -> .9.name=BRIDGET.scuttle, | AE17: =".."&A17&".postins.on="&IF(B17="x",1,IF(B17="y",1,0))&",mode="&IF(B17="x","AUTO_X",IF(B17="y","AUTO_Y","FX"))&"," -> ..9.postins.on=1,mode=AUTO_X, | AF17: ="."&N$2&".col="&_xlfn.XLOOKUP(N$4,refs!$A$2:$A$19,refs!$B$2:$B$19)&",name="&LEFT(N$6,16)&"," -> .9.col=8,name=.,
A18: 10 | B18: x | C18: x | D18: DYLAN.flotsam | E18: =COUNTA(F18:U18) -> 1 | O18: x | V18: =IF(E18=0,"x","") | W18: =_xlfn.XMATCH("x",F18:V18) -> 10 | X18: {=INDEX(F4:V4,W18)} -> Red | Y18: =_xlfn.XLOOKUP(X18,refs!$A$2:$A$19,refs!$B$2:$B$19) -> 9 | Z18: {=INDEX($F$3:$V$3,W18)} -> #D10 | AA18: =IF(C18="x",Y18,_xlfn.XLOOKUP(C3,refs!$A$2:$A$19,refs!$B$2:$B$19)) -> 9 | AB18: ="."&A18&".col="&AA18&",mute="&IF(C18="x",0,1)&"," -> .10.col=9,mute=0, | AC18: ="."&A18&".tags="&Z18&"," -> .10.tags=#D10, | AD18: ="."&A18&".name="&LEFT(D18,16)&"," -> .10.name=DYLAN.flotsam, | AE18: =".."&A18&".postins.on="&IF(B18="x",1,IF(B18="y",1,0))&",mode="&IF(B18="x","AUTO_X",IF(B18="y","AUTO_Y","FX"))&"," -> ..10.postins.on=1,mode=AUTO_X, | AF18: ="."&O$2&".col="&_xlfn.XLOOKUP(O$4,refs!$A$2:$A$19,refs!$B$2:$B$19)&",name="&LEFT(O$6,16)&"," -> .10.col=9,name=.,
A19: 11 | B19: x | C19: x | D19: ELIJAH.jetsam | E19: =COUNTA(F19:U19) -> 1 | P19: x | V19: =IF(E19=0,"x","") | W19: =_xlfn.XMATCH("x",F19:V19) -> 11 | X19: {=INDEX(F4:V4,W19)} -> Coral | Y19: =_xlfn.XLOOKUP(X19,refs!$A$2:$A$19,refs!$B$2:$B$19) -> 10 | Z19: {=INDEX($F$3:$V$3,W19)} -> #D11 | AA19: =IF(C19="x",Y19,_xlfn.XLOOKUP(C3,refs!$A$2:$A$19,refs!$B$2:$B$19)) -> 10 | AB19: ="."&A19&".col="&AA19&",mute="&IF(C19="x",0,1)&"," -> .11.col=10,mute=0, | AC19: ="."&A19&".tags="&Z19&"," -> .11.tags=#D11, | AD19: ="."&A19&".name="&LEFT(D19,16)&"," -> .11.name=ELIJAH.jetsam, | AE19: =".."&A19&".postins.on="&IF(B19="x",1,IF(B19="y",1,0))&",mode="&IF(B19="x","AUTO_X",IF(B19="y","AUTO_Y","FX"))&"," -> ..11.postins.on=1,mode=AUTO_X, | AF19: ="."&P$2&".col="&_xlfn.XLOOKUP(P$4,refs!$A$2:$A$19,refs!$B$2:$B$19)&",name="&LEFT(P$6,16)&"," -> .11.col=10,name=OS,
A20: 12 | B20: x | C20: x | D20: SYR.pilot | E20: =COUNTA(F20:U20) -> 1 | Q20: x | V20: =IF(E20=0,"x","") | W20: =_xlfn.XMATCH("x",F20:V20) -> 12 | X20: {=INDEX(F4:V4,W20)} -> Pink | Y20: =_xlfn.XLOOKUP(X20,refs!$A$2:$A$19,refs!$B$2:$B$19) -> 11 | Z20: {=INDEX($F$3:$V$3,W20)} -> #D12 | AA20: =IF(C20="x",Y20,_xlfn.XLOOKUP(C3,refs!$A$2:$A$19,refs!$B$2:$B$19)) -> 11 | AB20: ="."&A20&".col="&AA20&",mute="&IF(C20="x",0,1)&"," -> .12.col=11,mute=0, | AC20: ="."&A20&".tags="&Z20&"," -> .12.tags=#D12, | AD20: ="."&A20&".name="&LEFT(D20,16)&"," -> .12.name=SYR.pilot, | AE20: =".."&A20&".postins.on="&IF(B20="x",1,IF(B20="y",1,0))&",mode="&IF(B20="x","AUTO_X",IF(B20="y","AUTO_Y","FX"))&"," -> ..12.postins.on=1,mode=AUTO_X, | AF20: ="."&Q$2&".col="&_xlfn.XLOOKUP(Q$4,refs!$A$2:$A$19,refs!$B$2:$B$19)&",name="&LEFT(Q$6,16)&"," -> .12.col=11,name=VOX+.VRB,
A21: 13 | B21: y | C21: x | D21: KATELYN.aquata | E21: =COUNTA(F21:U21) -> 1 | R21: x | V21: =IF(E21=0,"x","") | W21: =_xlfn.XMATCH("x",F21:V21) -> 13 | X21: {=INDEX(F4:V4,W21)} -> DarkV | Y21: =_xlfn.XLOOKUP(X21,refs!$A$2:$A$19,refs!$B$2:$B$19) -> 12 | Z21: {=INDEX($F$3:$V$3,W21)} -> #D13 | AA21: =IF(C21="x",Y21,_xlfn.XLOOKUP(C3,refs!$A$2:$A$19,refs!$B$2:$B$19)) -> 12 | AB21: ="."&A21&".col="&AA21&",mute="&IF(C21="x",0,1)&"," -> .13.col=12,mute=0, | AC21: ="."&A21&".tags="&Z21&"," -> .13.tags=#D13, | AD21: ="."&A21&".name="&LEFT(D21,16)&"," -> .13.name=KATELYN.aquata, | AE21: =".."&A21&".postins.on="&IF(B21="x",1,IF(B21="y",1,0))&",mode="&IF(B21="x","AUTO_X",IF(B21="y","AUTO_Y","FX"))&"," -> ..13.postins.on=1,mode=AUTO_Y, | AF21: ="."&R$2&".col="&_xlfn.XLOOKUP(R$4,refs!$A$2:$A$19,refs!$B$2:$B$19)&",name="&LEFT(R$6,16)&"," -> .13.col=12,name=VOX_.VRB,
A22: 14 | B22: y | C22: x | D22: NADJA.adrina | E22: =COUNTA(F22:U22) -> 1 | S22: x | V22: =IF(E22=0,"x","") | W22: =_xlfn.XMATCH("x",F22:V22) -> 14 | X22: {=INDEX(F4:V4,W22)} -> Gold | Y22: =_xlfn.XLOOKUP(X22,refs!$A$2:$A$19,refs!$B$2:$B$19) -> 13 | Z22: {=INDEX($F$3:$V$3,W22)} -> #D14 | AA22: =IF(C22="x",Y22,_xlfn.XLOOKUP(C3,refs!$A$2:$A$19,refs!$B$2:$B$19)) -> 13 | AB22: ="."&A22&".col="&AA22&",mute="&IF(C22="x",0,1)&"," -> .14.col=13,mute=0, | AC22: ="."&A22&".tags="&Z22&"," -> .14.tags=#D14, | AD22: ="."&A22&".name="&LEFT(D22,16)&"," -> .14.name=NADJA.adrina, | AE22: =".."&A22&".postins.on="&IF(B22="x",1,IF(B22="y",1,0))&",mode="&IF(B22="x","AUTO_X",IF(B22="y","AUTO_Y","FX"))&"," -> ..14.postins.on=1,mode=AUTO_Y, | AF22: ="."&S$2&".col="&_xlfn.XLOOKUP(S$4,refs!$A$2:$A$19,refs!$B$2:$B$19)&",name="&LEFT(S$6,16)&"," -> .14.col=13,name=INST+.VRB,
A23: 15 | B23: y | C23: x | D23: RACHELP.arista | E23: =COUNTA(F23:U23) -> 1 | T23: x | V23: =IF(E23=0,"x","") | W23: =_xlfn.XMATCH("x",F23:V23) -> 15 | X23: {=INDEX(F4:V4,W23)} -> LightB | Y23: =_xlfn.XLOOKUP(X23,refs!$A$2:$A$19,refs!$B$2:$B$19) -> 14 | Z23: {=INDEX($F$3:$V$3,W23)} -> #D15 | AA23: =IF(C23="x",Y23,_xlfn.XLOOKUP(C3,refs!$A$2:$A$19,refs!$B$2:$B$19)) -> 14 | AB23: ="."&A23&".col="&AA23&",mute="&IF(C23="x",0,1)&"," -> .15.col=14,mute=0, | AC23: ="."&A23&".tags="&Z23&"," -> .15.tags=#D15, | AD23: ="."&A23&".name="&LEFT(D23,16)&"," -> .15.name=RACHELP.arista, | AE23: =".."&A23&".postins.on="&IF(B23="x",1,IF(B23="y",1,0))&",mode="&IF(B23="x","AUTO_X",IF(B23="y","AUTO_Y","FX"))&"," -> ..15.postins.on=1,mode=AUTO_Y, | AF23: ="."&T$2&".col="&_xlfn.XLOOKUP(T$4,refs!$A$2:$A$19,refs!$B$2:$B$19)&",name="&LEFT(T$6,16)&"," -> .15.col=14,name=INST_.VRB,
A24: 16 | B24: y | C24: x | D24: MAURA.atina | E24: =COUNTA(F24:U24) -> 1 | U24: x | V24: =IF(E24=0,"x","") | W24: =_xlfn.XMATCH("x",F24:V24) -> 16 | X24: {=INDEX(F4:V4,W24)} -> Tangerine | Y24: =_xlfn.XLOOKUP(X24,refs!$A$2:$A$19,refs!$B$2:$B$19) -> 15 | Z24: {=INDEX($F$3:$V$3,W24)} -> #D16 | AA24: =IF(C24="x",Y24,_xlfn.XLOOKUP(C3,refs!$A$2:$A$19,refs!$B$2:$B$19)) -> 15 | AB24: ="."&A24&".col="&AA24&",mute="&IF(C24="x",0,1)&"," -> .16.col=15,mute=0, | AC24: ="."&A24&".tags="&Z24&"," -> .16.tags=#D16, | AD24: ="."&A24&".name="&LEFT(D24,16)&"," -> .16.name=MAURA.atina, | AE24: =".."&A24&".postins.on="&IF(B24="x",1,IF(B24="y",1,0))&",mode="&IF(B24="x","AUTO_X",IF(B24="y","AUTO_Y","FX"))&"," -> ..16.postins.on=1,mode=AUTO_Y, | AF24: ="."&U$2&".col="&_xlfn.XLOOKUP(U$4,refs!$A$2:$A$19,refs!$B$2:$B$19)&",name="&LEFT(U$6,16)&"," -> .16.col=15,name=MAINS,
A25: 17 | C25: x | D25: JACKLYN.adella | E25: =COUNTA(F25:U25) -> 0 | V25: =IF(E25=0,"x","") -> x | W25: =_xlfn.XMATCH("x",F25:V25) -> 17 | X25: {=INDEX(F4:V4,W25)} -> White | Y25: =_xlfn.XLOOKUP(X25,refs!$A$2:$A$19,refs!$B$2:$B$19) -> 18 | Z25: {=INDEX($F$3:$V$3,W25)} | AA25: =IF(C25="x",Y25,_xlfn.XLOOKUP(C3,refs!$A$2:$A$19,refs!$B$2:$B$19)) -> 18 | AB25: ="."&A25&".col="&AA25&",mute="&IF(C25="x",0,1)&"," -> .17.col=18,mute=0, | AC25: ="."&A25&".tags="&Z25&"," -> .17.tags=, | AD25: ="."&A25&".name="&LEFT(D25,16)&"," -> .17.name=JACKLYN.adella, | AE25: =".."&A25&".postins.on="&IF(B25="x",1,IF(B25="y",1,0))&",mode="&IF(B25="x","AUTO_X",IF(B25="y","AUTO_Y","FX"))&"," -> ..17.postins.on=0,mode=FX, | AF25: ="/cfg.amix.x="&IF(C4="x",1,0)&",/cfg.amix.y="&IF(C6="x",1,0)&"," -> /cfg.amix.x=1,/cfg.amix.y=1,
A26: 18 | C26: x | D26: SARAH.allana | E26: =COUNTA(F26:U26) -> 0 | V26: =IF(E26=0,"x","") -> x | W26: =_xlfn.XMATCH("x",F26:V26) -> 17 | X26: {=INDEX(F4:V4,W26)} -> White | Y26: =_xlfn.XLOOKUP(X26,refs!$A$2:$A$19,refs!$B$2:$B$19) -> 18 | Z26: {=INDEX($F$3:$V$3,W26)} | AA26: =IF(C26="x",Y26,_xlfn.XLOOKUP(C3,refs!$A$2:$A$19,refs!$B$2:$B$19)) -> 18 | AB26: ="."&A26&".col="&AA26&",mute="&IF(C26="x",0,1)&"," -> .18.col=18,mute=0, | AC26: ="."&A26&".tags="&Z26&"," -> .18.tags=, | AD26: ="."&A26&".name="&LEFT(D26,16)&"," -> .18.name=SARAH.allana, | AE26: =".."&A26&".postins.on="&IF(B26="x",1,IF(B26="y",1,0))&",mode="&IF(B26="x","AUTO_X",IF(B26="y","AUTO_Y","FX"))&"," -> ..18.postins.on=0,mode=FX,
A27: 19 | C27: x | D27: REBECCA.maid | E27: =COUNTA(F27:U27) -> 0 | V27: =IF(E27=0,"x","") -> x | W27: =_xlfn.XMATCH("x",F27:V27) -> 17 | X27: {=INDEX(F4:V4,W27)} -> White | Y27: =_xlfn.XLOOKUP(X27,refs!$A$2:$A$19,refs!$B$2:$B$19) -> 18 | Z27: {=INDEX($F$3:$V$3,W27)} | AA27: =IF(C27="x",Y27,_xlfn.XLOOKUP(C3,refs!$A$2:$A$19,refs!$B$2:$B$19)) -> 18 | AB27: ="."&A27&".col="&AA27&",mute="&IF(C27="x",0,1)&"," -> .19.col=18,mute=0, | AC27: ="."&A27&".tags="&Z27&"," -> .19.tags=, | AD27: ="."&A27&".name="&LEFT(D27,16)&"," -> .19.name=REBECCA.maid, | AE27: =".."&A27&".postins.on="&IF(B27="x",1,IF(B27="y",1,0))&",mode="&IF(B27="x","AUTO_X",IF(B27="y","AUTO_Y","FX"))&"," -> ..19.postins.on=0,mode=FX,
A28: 20 | C28: x | D28: ANNIE.maid | E28: =COUNTA(F28:U28) -> 0 | V28: =IF(E28=0,"x","") -> x | W28: =_xlfn.XMATCH("x",F28:V28) -> 17 | X28: {=INDEX(F4:V4,W28)} -> White | Y28: =_xlfn.XLOOKUP(X28,refs!$A$2:$A$19,refs!$B$2:$B$19) -> 18 | Z28: {=INDEX($F$3:$V$3,W28)} | AA28: =IF(C28="x",Y28,_xlfn.XLOOKUP(C3,refs!$A$2:$A$19,refs!$B$2:$B$19)) -> 18 | AB28: ="."&A28&".col="&AA28&",mute="&IF(C28="x",0,1)&"," -> .20.col=18,mute=0, | AC28: ="."&A28&".tags="&Z28&"," -> .20.tags=, | AD28: ="."&A28&".name="&LEFT(D28,16)&"," -> .20.name=ANNIE.maid, | AE28: =".."&A28&".postins.on="&IF(B28="x",1,IF(B28="y",1,0))&",mode="&IF(B28="x","AUTO_X",IF(B28="y","AUTO_Y","FX"))&"," -> ..20.postins.on=0,mode=FX,
A29: 21 | C29: x | D29: KARA.maid | E29: =COUNTA(F29:U29) -> 0 | V29: =IF(E29=0,"x","") -> x | W29: =_xlfn.XMATCH("x",F29:V29) -> 17 | X29: {=INDEX(F4:V4,W29)} -> White | Y29: =_xlfn.XLOOKUP(X29,refs!$A$2:$A$19,refs!$B$2:$B$19) -> 18 | Z29: {=INDEX($F$3:$V$3,W29)} | AA29: =IF(C29="x",Y29,_xlfn.XLOOKUP(C3,refs!$A$2:$A$19,refs!$B$2:$B$19)) -> 18 | AB29: ="."&A29&".col="&AA29&",mute="&IF(C29="x",0,1)&"," -> .21.col=18,mute=0, | AC29: ="."&A29&".tags="&Z29&"," -> .21.tags=, | AD29: ="/ch."&A29&".name="&LEFT(D29,16)&"," -> /ch.21.name=KARA.maid, | AE29: ="/ch."&A29&".postins.on="&IF(B29="x",1,IF(B29="y",1,0))&",mode="&IF(B29="x","AUTO_X",IF(B29="y","AUTO_Y","FX"))&"," -> /ch.21.postins.on=0,mode=FX,
A30: 22 | C30: x | D30: GENEVIEVE.leeward | E30: =COUNTA(F30:U30) -> 0 | V30: =IF(E30=0,"x","") -> x | W30: =_xlfn.XMATCH("x",F30:V30) -> 17 | X30: {=INDEX(F4:V4,W30)} -> White | Y30: =_xlfn.XLOOKUP(X30,refs!$A$2:$A$19,refs!$B$2:$B$19) -> 18 | Z30: {=INDEX($F$3:$V$3,W30)} | AA30: =IF(C30="x",Y30,_xlfn.XLOOKUP(C3,refs!$A$2:$A$19,refs!$B$2:$B$19)) -> 18 | AB30: ="."&A30&".col="&AA30&",mute="&IF(C30="x",0,1)&"," -> .22.col=18,mute=0, | AC30: ="."&A30&".tags="&Z30&"," -> .22.tags=, | AD30: ="."&A30&".name="&LEFT(D30,16)&"," -> .22.name=GENEVIEVE.leewar, | AE30: =".."&A30&".postins.on="&IF(B30="x",1,IF(B30="y",1,0))&",mode="&IF(B30="x","AUTO_X",IF(B30="y","AUTO_Y","FX"))&"," -> ..22.postins.on=0,mode=FX,
A31: 23 | C31: x | D31: JOCELYN.windward | E31: =COUNTA(F31:U31) -> 0 | V31: =IF(E31=0,"x","") -> x | W31: =_xlfn.XMATCH("x",F31:V31) -> 17 | X31: {=INDEX(F4:V4,W31)} -> White | Y31: =_xlfn.XLOOKUP(X31,refs!$A$2:$A$19,refs!$B$2:$B$19) -> 18 | Z31: {=INDEX($F$3:$V$3,W31)} | AA31: =IF(C31="x",Y31,_xlfn.XLOOKUP(C3,refs!$A$2:$A$19,refs!$B$2:$B$19)) -> 18 | AB31: ="."&A31&".col="&AA31&",mute="&IF(C31="x",0,1)&"," -> .23.col=18,mute=0, | AC31: ="."&A31&".tags="&Z31&"," -> .23.tags=, | AD31: ="."&A31&".name="&LEFT(D31,16)&"," -> .23.name=JOCELYN.windward, | AE31: =".."&A31&".postins.on="&IF(B31="x",1,IF(B31="y",1,0))&",mode="&IF(B31="x","AUTO_X",IF(B31="y","AUTO_Y","FX"))&"," -> ..23.postins.on=0,mode=FX,
A32: 24 | D32: . | E32: =COUNTA(F32:U32) -> 0 | V32: =IF(E32=0,"x","") -> x | W32: =_xlfn.XMATCH("x",F32:V32) -> 17 | X32: {=INDEX(F4:V4,W32)} -> White | Y32: =_xlfn.XLOOKUP(X32,refs!$A$2:$A$19,refs!$B$2:$B$19) -> 18 | Z32: {=INDEX($F$3:$V$3,W32)} | AA32: =IF(C32="x",Y32,_xlfn.XLOOKUP(C3,refs!$A$2:$A$19,refs!$B$2:$B$19)) -> 17 | AB32: ="."&A32&".col="&AA32&",mute="&IF(C32="x",0,1)&"," -> .24.col=17,mute=1, | AC32: ="."&A32&".tags="&Z32&"," -> .24.tags=, | AD32: ="."&A32&".name="&LEFT(D32,16)&"," -> .24.name=., | AE32: =".."&A32&".postins.on="&IF(B32="x",1,IF(B32="y",1,0))&",mode="&IF(B32="x","AUTO_X",IF(B32="y","AUTO_Y","FX"))&"," -> ..24.postins.on=0,mode=FX,
A33: 25 | C33: x | D33: ROBERT.sail | E33: =COUNTA(F33:U33) -> 0 | V33: =IF(E33=0,"x","") -> x | W33: =_xlfn.XMATCH("x",F33:V33) -> 17 | X33: {=INDEX(F4:V4,W33)} -> White | Y33: =_xlfn.XLOOKUP(X33,refs!$A$2:$A$19,refs!$B$2:$B$19) -> 18 | Z33: {=INDEX($F$3:$V$3,W33)} | AA33: =IF(C33="x",Y33,_xlfn.XLOOKUP(C3,refs!$A$2:$A$19,refs!$B$2:$B$19)) -> 18 | AB33: ="."&A33&".col="&AA33&",mute="&IF(C33="x",0,1)&"," -> .25.col=18,mute=0, | AC33: ="."&A33&".tags="&Z33&"," -> .25.tags=, | AD33: ="."&A33&".name="&LEFT(D33,16)&"," -> .25.name=ROBERT.sail, | AE33: =".."&A33&".postins.on="&IF(B33="x",1,IF(B33="y",1,0))&",mode="&IF(B33="x","AUTO_X",IF(B33="y","AUTO_Y","FX"))&"," -> ..25.postins.on=0,mode=FX,
A34: 26 | C34: x | D34: TOM.sail | E34: =COUNTA(F34:U34) -> 0 | V34: =IF(E34=0,"x","") -> x | W34: =_xlfn.XMATCH("x",F34:V34) -> 17 | X34: {=INDEX(F4:V4,W34)} -> White | Y34: =_xlfn.XLOOKUP(X34,refs!$A$2:$A$19,refs!$B$2:$B$19) -> 18 | Z34: {=INDEX($F$3:$V$3,W34)} | AA34: =IF(C34="x",Y34,_xlfn.XLOOKUP(C3,refs!$A$2:$A$19,refs!$B$2:$B$19)) -> 18 | AB34: ="."&A34&".col="&AA34&",mute="&IF(C34="x",0,1)&"," -> .26.col=18,mute=0, | AC34: ="."&A34&".tags="&Z34&"," -> .26.tags=, | AD34: ="."&A34&".name="&LEFT(D34,16)&"," -> .26.name=TOM.sail, | AE34: =".."&A34&".postins.on="&IF(B34="x",1,IF(B34="y",1,0))&",mode="&IF(B34="x","AUTO_X",IF(B34="y","AUTO_Y","FX"))&"," -> ..26.postins.on=0,mode=FX,
A35: 27 | C35: x | D35: BILL.sail | E35: =COUNTA(F35:U35) -> 0 | V35: =IF(E35=0,"x","") -> x | W35: =_xlfn.XMATCH("x",F35:V35) -> 17 | X35: {=INDEX(F4:V4,W35)} -> White | Y35: =_xlfn.XLOOKUP(X35,refs!$A$2:$A$19,refs!$B$2:$B$19) -> 18 | Z35: {=INDEX($F$3:$V$3,W35)} | AA35: =IF(C35="x",Y35,_xlfn.XLOOKUP(C3,refs!$A$2:$A$19,refs!$B$2:$B$19)) -> 18 | AB35: ="."&A35&".col="&AA35&",mute="&IF(C35="x",0,1)&"," -> .27.col=18,mute=0, | AC35: ="."&A35&".tags="&Z35&"," -> .27.tags=, | AD35: ="."&A35&".name="&LEFT(D35,16)&"," -> .27.name=BILL.sail, | AE35: =".."&A35&".postins.on="&IF(B35="x",1,IF(B35="y",1,0))&",mode="&IF(B35="x","AUTO_X",IF(B35="y","AUTO_Y","FX"))&"," -> ..27.postins.on=0,mode=FX,
A36: 28 | C36: x | D36: DENNIS.sail | E36: =COUNTA(F36:U36) -> 0 | V36: =IF(E36=0,"x","") -> x | W36: =_xlfn.XMATCH("x",F36:V36) -> 17 | X36: {=INDEX(F4:V4,W36)} -> White | Y36: =_xlfn.XLOOKUP(X36,refs!$A$2:$A$19,refs!$B$2:$B$19) -> 18 | Z36: {=INDEX($F$3:$V$3,W36)} | AA36: =IF(C36="x",Y36,_xlfn.XLOOKUP(C3,refs!$A$2:$A$19,refs!$B$2:$B$19)) -> 18 | AB36: ="."&A36&".col="&AA36&",mute="&IF(C36="x",0,1)&"," -> .28.col=18,mute=0, | AC36: ="."&A36&".tags="&Z36&"," -> .28.tags=, | AD36: ="."&A36&".name="&LEFT(D36,16)&"," -> .28.name=DENNIS.sail, | AE36: =".."&A36&".postins.on="&IF(B36="x",1,IF(B36="y",1,0))&",mode="&IF(B36="x","AUTO_X",IF(B36="y","AUTO_Y","FX"))&"," -> ..28.postins.on=0,mode=FX,
A37: 29 | C37: x | D37: JOSHUA.sail | E37: =COUNTA(F37:U37) -> 0 | V37: =IF(E37=0,"x","") -> x | W37: =_xlfn.XMATCH("x",F37:V37) -> 17 | X37: {=INDEX(F4:V4,W37)} -> White | Y37: =_xlfn.XLOOKUP(X37,refs!$A$2:$A$19,refs!$B$2:$B$19) -> 18 | Z37: {=INDEX($F$3:$V$3,W37)} | AA37: =IF(C37="x",Y37,_xlfn.XLOOKUP(C3,refs!$A$2:$A$19,refs!$B$2:$B$19)) -> 18 | AB37: ="."&A37&".col="&AA37&",mute="&IF(C37="x",0,1)&"," -> .29.col=18,mute=0, | AC37: ="."&A37&".tags="&Z37&"," -> .29.tags=, | AD37: ="."&A37&".name="&LEFT(D37,16)&"," -> .29.name=JOSHUA.sail, | AE37: =".."&A37&".postins.on="&IF(B37="x",1,IF(B37="y",1,0))&",mode="&IF(B37="x","AUTO_X",IF(B37="y","AUTO_Y","FX"))&"," -> ..29.postins.on=0,mode=FX,
A38: 30 | C38: x | D38: RAY.sail | E38: =COUNTA(F38:U38) -> 0 | V38: =IF(E38=0,"x","") -> x | W38: =_xlfn.XMATCH("x",F38:V38) -> 17 | X38: {=INDEX(F4:V4,W38)} -> White | Y38: =_xlfn.XLOOKUP(X38,refs!$A$2:$A$19,refs!$B$2:$B$19) -> 18 | Z38: {=INDEX($F$3:$V$3,W38)} | AA38: =IF(C38="x",Y38,_xlfn.XLOOKUP(C3,refs!$A$2:$A$19,refs!$B$2:$B$19)) -> 18 | AB38: ="."&A38&".col="&AA38&",mute="&IF(C38="x",0,1)&"," -> .30.col=18,mute=0, | AC38: ="."&A38&".tags="&Z38&"," -> .30.tags=, | AD38: ="."&A38&".name="&LEFT(D38,16)&"," -> .30.name=RAY.sail, | AE38: =".."&A38&".postins.on="&IF(B38="x",1,IF(B38="y",1,0))&",mode="&IF(B38="x","AUTO_X",IF(B38="y","AUTO_Y","FX"))&"," -> ..30.postins.on=0,mode=FX,
A39: 31 | C39: x | D39: WILL.sail | E39: =COUNTA(F39:U39) -> 0 | V39: =IF(E39=0,"x","") -> x | W39: =_xlfn.XMATCH("x",F39:V39) -> 17 | X39: {=INDEX(F4:V4,W39)} -> White | Y39: =_xlfn.XLOOKUP(X39,refs!$A$2:$A$19,refs!$B$2:$B$19) -> 18 | Z39: {=INDEX($F$3:$V$3,W39)} | AA39: =IF(C39="x",Y39,_xlfn.XLOOKUP(C3,refs!$A$2:$A$19,refs!$B$2:$B$19)) -> 18 | AB39: ="."&A39&".col="&AA39&",mute="&IF(C39="x",0,1)&"," -> .31.col=18,mute=0, | AC39: ="."&A39&".tags="&Z39&"," -> .31.tags=, | AD39: ="."&A39&".name="&LEFT(D39,16)&"," -> .31.name=WILL.sail, | AE39: =".."&A39&".postins.on="&IF(B39="x",1,IF(B39="y",1,0))&",mode="&IF(B39="x","AUTO_X",IF(B39="y","AUTO_Y","FX"))&"," -> ..31.postins.on=0,mode=FX,
A40: 32 | C40: x | D40: PRISCILLA | E40: =COUNTA(F40:U40) -> 0 | V40: =IF(E40=0,"x","") -> x | W40: =_xlfn.XMATCH("x",F40:V40) -> 17 | X40: {=INDEX(F4:V4,W40)} -> White | Y40: =_xlfn.XLOOKUP(X40,refs!$A$2:$A$19,refs!$B$2:$B$19) -> 18 | Z40: {=INDEX($F$3:$V$3,W40)} | AA40: =IF(C40="x",Y40,_xlfn.XLOOKUP(C3,refs!$A$2:$A$19,refs!$B$2:$B$19)) -> 18 | AB40: ="."&A40&".col="&AA40&",mute="&IF(C40="x",0,1)&"," -> .32.col=18,mute=0, | AC40: ="."&A40&".tags="&Z40&"," -> .32.tags=, | AD40: ="."&A40&".name="&LEFT(D40,16)&"," -> .32.name=PRISCILLA, | AE40: =".."&A40&".postins.on="&IF(B40="x",1,IF(B40="y",1,0))&",mode="&IF(B40="x","AUTO_X",IF(B40="y","AUTO_Y","FX"))&"," -> ..32.postins.on=0,mode=FX,
A41: 33 | C41: x | D41: RACHELS | E41: =COUNTA(F41:U41) -> 0 | V41: =IF(E41=0,"x","") -> x | W41: =_xlfn.XMATCH("x",F41:V41) -> 17 | X41: {=INDEX(F4:V4,W41)} -> White | Y41: =_xlfn.XLOOKUP(X41,refs!$A$2:$A$19,refs!$B$2:$B$19) -> 18 | Z41: {=INDEX($F$3:$V$3,W41)} | AA41: =IF(C41="x",Y41,_xlfn.XLOOKUP(C3,refs!$A$2:$A$19,refs!$B$2:$B$19)) -> 18 | AB41: ="."&A41&".col="&AA41&",mute="&IF(C41="x",0,1)&"," -> .33.col=18,mute=0, | AC41: ="."&A41&".tags="&Z41&"," -> .33.tags=, | AD41: ="."&A41&".name="&LEFT(D41,16)&"," -> .33.name=RACHELS, | AE41: =".."&A41&".postins.on="&IF(B41="x",1,IF(B41="y",1,0))&",mode="&IF(B41="x","AUTO_X",IF(B41="y","AUTO_Y","FX"))&"," -> ..33.postins.on=0,mode=FX,
A42: 34 | C42: x | D42: JEN | E42: =COUNTA(F42:U42) -> 0 | V42: =IF(E42=0,"x","") -> x | W42: =_xlfn.XMATCH("x",F42:V42) -> 17 | X42: {=INDEX(F4:V4,W42)} -> White | Y42: =_xlfn.XLOOKUP(X42,refs!$A$2:$A$19,refs!$B$2:$B$19) -> 18 | Z42: {=INDEX($F$3:$V$3,W42)} | AA42: =IF(C42="x",Y42,_xlfn.XLOOKUP(C3,refs!$A$2:$A$19,refs!$B$2:$B$19)) -> 18 | AB42: ="."&A42&".col="&AA42&",mute="&IF(C42="x",0,1)&"," -> .34.col=18,mute=0, | AC42: ="."&A42&".tags="&Z42&"," -> .34.tags=, | AD42: ="."&A42&".name="&LEFT(D42,16)&"," -> .34.name=JEN, | AE42: =".."&A42&".postins.on="&IF(B42="x",1,IF(B42="y",1,0))&",mode="&IF(B42="x","AUTO_X",IF(B42="y","AUTO_Y","FX"))&"," -> ..34.postins.on=0,mode=FX,
...

Sheet EXPORT
A1: {=IF(INDEX(CUEs!$A:$A,INT((ROW()-1)/7)*57+MOD(ROW()-1,7)+50)<>"","set "&INDEX(CUEs!$A:$A,INT((ROW()-1)/7)*57+MOD(ROW()-1,7)+50)&"=/ s "&INDEX(CUEs!$B:$B,INT((ROW()-1)/7)*57+MOD(ROW()-1,7)+50),"")} -> set w1_0001_ch_col_mute=/ s /ch.1.col=7,mute=0,.2.col=7,mute=0,.3.col=7,mute=0,.4.col=7,mute=0,.5.col=4,mute=0,.6.col=5,mute=0,.7.col=6,mute=0,.8.col=7,mute=0,.9.col=8,mute=0,.10.col=9,mute=0,.11.col=10,mute=0,.12.col=11,mute=0,.13.col=12,mute=0,.14.col=13,mute=0,.15.col=14,mute=0,.16.col=15,mute=0,.17.col=18,mute=0,.18.col=18,mute=0,.19.col=18,mute=0,.20.col=18,mute=0,.21.col=18,mute=0,.22.col=18,mute=0,.23.col=18,mute=0,.24.col=17,mute=1,.25.col=18,mute=0,.26.col=18,mute=0,.27.col=18,mute=0,.28.col=18,mute=0,.29.col=18,mute=0,.30.col=18,mute=0,.31.col=18,mute=0,.32.col=18,mute=0,.33.col=18,mute=0,.34.col=18,mute=0,.35.col=18,mute=0,.36.col=18,mute=0,.37.col=17,mute=1,.38.col=18,mute=0,.39.col=18,mute=0,.40.col=18,mute=0,
A2: {=IF(INDEX(CUEs!$A:$A,INT((ROW()-1)/7)*57+MOD(ROW()-1,7)+50)<>"","set "&INDEX(CUEs!$A:$A,INT((ROW()-1)/7)*57+MOD(ROW()-1,7)+50)&"=/ s "&INDEX(CUEs!$B:$B,INT((ROW()-1)/7)*57+MOD(ROW()-1,7)+50),"")} -> set w1_0001_ch_tags=/ s /ch.1.tags=#D8,.2.tags=#D1,.3.tags=#D1,.4.tags=#D1,.5.tags=#D5,.6.tags=#D6,.7.tags=#D7,.8.tags=#D8,.9.tags=#D9,.10.tags=#D10,.11.tags=#D11,.12.tags=#D12,.13.tags=#D13,.14.tags=#D14,.15.tags=#D15,.16.tags=#D16,.17.tags=,.18.tags=,.19.tags=,.20.tags=,.21.tags=,.22.tags=,.23.tags=,.24.tags=,.25.tags=,.26.tags=,.27.tags=,.28.tags=,.29.tags=,.30.tags=,.31.tags=,.32.tags=,.33.tags=,.34.tags=,.35.tags=,.36.tags=,.37.tags=,.38.tags=,.39.tags=,.40.tags=,
A3: {=IF(INDEX(CUEs!$A:$A,INT((ROW()-1)/7)*57+MOD(ROW()-1,7)+50)<>"","set "&INDEX(CUEs!$A:$A,INT((ROW()-1)/7)*57+MOD(ROW()-1,7)+50)&"=/ s "&INDEX(CUEs!$B:$B,INT((ROW()-1)/7)*57+MOD(ROW()-1,7)+50),"")} -> set w1_0001_ch_names_a=/ s /ch.1.name=CAROLINE.ariel,.2.name=GABE.eric,.3.name=KEITH.grimsby,.4.name=CHADLEY.sebastia,.5.name=ANNA.flounder,.6.name=MARGERY.ursula,.7.name=JOHN.triton,.8.name=JUDAH.chefL,.9.name=BRIDGET.scuttle,.10.name=DYLAN.flotsam,.11.name=ELIJAH.jetsam,.12.name=SYR.pilot,.13.name=KATELYN.aquata,.14.name=NADJA.adrina,.15.name=RACHELP.arista,.16.name=MAURA.atina,.17.name=JACKLYN.adella,.18.name=SARAH.allana,.19.name=REBECCA.maid,.20.name=ANNIE.maid,
A4: {=IF(INDEX(CUEs!$A:$A,INT((ROW()-1)/7)*57+MOD(ROW()-1,7)+50)<>"","set "&INDEX(CUEs!$A:$A,INT((ROW()-1)/7)*57+MOD(ROW()-1,7)+50)&"=/ s "&INDEX(CUEs!$B:$B,INT((ROW()-1)/7)*57+MOD(ROW()-1,7)+50),"")} -> set w1_0001_ch_names_b=/ s /ch.21.name=KARA.maid,.22.name=GENEVIEVE.leewar,.23.name=JOCELYN.windward,.24.name=.,.25.name=ROBERT.sail,.26.name=TOM.sail,.27.name=BILL.sail,.28.name=DENNIS.sail,.29.name=JOSHUA.sail,.30.name=RAY.sail,.31.name=WILL.sail,.32.name=PRISCILLA,.33.name=RACHELS,.34.name=JEN,.35.name=OS1,.36.name=OS2,.37.name=unusedos,.38.name=VOX.fr.ext,.39.name=INS.fr.ext,.40.name=pass.fr.w2,
A5: {=IF(INDEX(CUEs!$A:$A,INT((ROW()-1)/7)*57+MOD(ROW()-1,7)+50)<>"","set "&INDEX(CUEs!$A:$A,INT((ROW()-1)/7)*57+MOD(ROW()-1,7)+50)&"=/ s "&INDEX(CUEs!$B:$B,INT((ROW()-1)/7)*57+MOD(ROW()-1,7)+50),"")} -> set w1_0001_ch_postins_a=/ s /ch.1.postins.on=1,mode=AUTO_X,..2.postins.on=1,mode=AUTO_X,..3.postins.on=1,mode=AUTO_X,..4.postins.on=0,mode=FX,..5.postins.on=1,mode=AUTO_X,..6.postins.on=1,mode=AUTO_X,..7.postins.on=1,mode=AUTO_X,..8.postins.on=1,mode=AUTO_X,..9.postins.on=1,mode=AUTO_X,..10.postins.on=1,mode=AUTO_X,..11.postins.on=1,mode=AUTO_X,..12.postins.on=1,mode=AUTO_X,..13.postins.on=1,mode=AUTO_Y,..14.postins.on=1,mode=AUTO_Y,..15.postins.on=1,mode=AUTO_Y,..16.postins.on=1,mode=AUTO_Y,..17.postins.on=0,mode=FX,..18.postins.on=0,mode=FX,..19.postins.on=0,mode=FX,..20.postins.on=0,mode=FX,
A6: {=IF(INDEX(CUEs!$A:$A,INT((ROW()-1)/7)*57+MOD(ROW()-1,7)+50)<>"","set "&INDEX(CUEs!$A:$A,INT((ROW()-1)/7)*57+MOD(ROW()-1,7)+50)&"=/ s "&INDEX(CUEs!$B:$B,INT((ROW()-1)/7)*57+MOD(ROW()-1,7)+50),"")} -> set w1_0001_ch_postins_b=/ s /ch.21.postins.on=0,mode=FX,..22.postins.on=0,mode=FX,..23.postins.on=0,mode=FX,..24.postins.on=0,mode=FX,..25.postins.on=0,mode=FX,..26.postins.on=0,mode=FX,..27.postins.on=0,mode=FX,..28.postins.on=0,mode=FX,..29.postins.on=0,mode=FX,..30.postins.on=0,mode=FX,..31.postins.on=0,mode=FX,..32.postins.on=0,mode=FX,..33.postins.on=0,mode=FX,..34.postins.on=0,mode=FX,..35.postins.on=0,mode=FX,..36.postins.on=0,mode=FX,..37.postins.on=0,mode=FX,..38.postins.on=0,mode=FX,..39.postins.on=0,mode=FX,..40.postins.on=0,mode=FX,
A7: {=IF(INDEX(CUEs!$A:$A,INT((ROW()-1)/7)*57+MOD(ROW()-1,7)+50)<>"","set "&INDEX(CUEs!$A:$A,INT((ROW()-1)/7)*57+MOD(ROW()-1,7)+50)&"=/ s "&INDEX(CUEs!$B:$B,INT((ROW()-1)/7)*57+MOD(ROW()-1,7)+50),"")} -> set w1_0001_dcas_amix=/ s /dca.1.col=7,name=LEADS,.2.col=1,name=FlotJet,.3.col=2,name=Sail,.4.col=3,name=Sisters,.5.col=4,name=Maids,.6.col=5,name=LeeWind,.7.col=6,name=PrRaJen,.8.col=7,name=.,.9.col=8,name=.,.10.col=9,name=.,.11.col=10,name=OS,.12.col=11,name=VOX+.VRB,.13.col=12,name=VOX_.VRB,.14.col=13,name=INST+.VRB,.15.col=14,name=INST_.VRB,.16.col=15,name=MAINS,/cfg.amix.x=1,/cfg.amix.y=1,
A8: {=IF(INDEX(CUEs!$A:$A,INT((ROW()-1)/7)*57+MOD(ROW()-1,7)+50)<>"","set "&INDEX(CUEs!$A:$A,INT((ROW()-1)/7)*57+MOD(ROW()-1,7)+50)&"=/ s "&INDEX(CUEs!$B:$B,INT((ROW()-1)/7)*57+MOD(ROW()-1,7)+50),"")} -> set w1_0002_ch_col_mute=/ s /ch.1.col=13,mute=0,.2.col=13,mute=0,.3.col=13,mute=0,.4.col=13,mute=0,.5.col=13,mute=0,.6.col=13,mute=0,.7.col=13,mute=0,.8.col=13,mute=0,.9.col=13,mute=0,.10.col=10,mute=0,.11.col=10,mute=0,.12.col=8,mute=0,.13.col=11,mute=0,.14.col=11,mute=0,.15.col=11,mute=0,.16.col=11,mute=0,.17.col=11,mute=0,.18.col=11,mute=0,.19.col=5,mute=0,.20.col=5,mute=0,.21.col=5,mute=0,.22.col=4,mute=0,.23.col=4,mute=0,.24.col=17,mute=1,.25.col=8,mute=0,.26.col=8,mute=0,.27.col=8,mute=0,.28.col=8,mute=0,.29.col=8,mute=0,.30.col=8,mute=0,.31.col=8,mute=0,.32.col=2,mute=0,.33.col=2,mute=0,.34.col=2,mute=0,.35.col=3,mute=0,.36.col=3,mute=0,.37.col=17,mute=1,.38.col=18,mute=0,.39.col=18,mute=0,.40.col=18,mute=0,
A9: {=IF(INDEX(CUEs!$A:$A,INT((ROW()-1)/7)*57+MOD(ROW()-1,7)+50)<>"","set "&INDEX(CUEs!$A:$A,INT((ROW()-1)/7)*57+MOD(ROW()-1,7)+50)&"=/ s "&INDEX(CUEs!$B:$B,INT((ROW()-1)/7)*57+MOD(ROW()-1,7)+50),"")} -> set w1_0002_ch_tags=/ s /ch.1.tags=#D1,.2.tags=#D1,.3.tags=#D1,.4.tags=#D1,.5.tags=#D1,.6.tags=#D1,.7.tags=#D1,.8.tags=#D1,.9.tags=#D1,.10.tags=#D2,.11.tags=#D2,.12.tags=#D3,.13.tags=#D4,.14.tags=#D4,.15.tags=#D4,.16.tags=#D4,.17.tags=#D4,.18.tags=#D4,.19.tags=#D5,.20.tags=#D5,.21.tags=#D5,.22.tags=#D6,.23.tags=#D6,.24.tags=,.25.tags=#D3,.26.tags=#D3,.27.tags=#D3,.28.tags=#D3,.29.tags=#D3,.30.tags=#D3,.31.tags=#D3,.32.tags=#D7,.33.tags=#D7,.34.tags=#D7,.35.tags=#D11,.36.tags=#D11,.37.tags=,.38.tags=,.39.tags=,.40.tags=,
A10: {=IF(INDEX(CUEs!$A:$A,INT((ROW()-1)/7)*57+MOD(ROW()-1,7)+50)<>"","set "&INDEX(CUEs!$A:$A,INT((ROW()-1)/7)*57+MOD(ROW()-1,7)+50)&"=/ s "&INDEX(CUEs!$B:$B,INT((ROW()-1)/7)*57+MOD(ROW()-1,7)+50),"")} -> set w1_0002_ch_names_a=/ s /ch.1.name=CAROLINE.ariel,.2.name=GABE.eric,.3.name=KEITH.grimsby,.4.name=CHADLEY.sebastia,.5.name=ANNA.flounder,.6.name=MARGERY.ursula,.7.name=JOHN.triton,.8.name=JUDAH.chefL,.9.name=BRIDGET.scuttle,.10.name=DYLAN.flotsam,.11.name=ELIJAH.jetsam,.12.name=SYR.pilot,.13.name=KATELYN.aquata,.14.name=NADJA.adrina,.15.name=RACHELP.arista,.16.name=MAURA.atina,.17.name=JACKLYN.adella,.18.name=SARAH.allana,.19.name=REBECCA.maid,.20.name=ANNIE.maid,
A11: {=IF(INDEX(CUEs!$A:$A,INT((ROW()-1)/7)*57+MOD(ROW()-1,7)+50)<>"","set "&INDEX(CUEs!$A:$A,INT((ROW()-1)/7)*57+MOD(ROW()-1,7)+50)&"=/ s "&INDEX(CUEs!$B:$B,INT((ROW()-1)/7)*57+MOD(ROW()-1,7)+50),"")} -> set w1_0002_ch_names_b=/ s /ch.21.name=KARA.maid,.22.name=GENEVIEVE.leewar,.23.name=JOCELYN.windward,.24.name=.,.25.name=ROBERT.sail,.26.name=TOM.sail,.27.name=BILL.sail,.28.name=DENNIS.sail,.29.name=JOSHUA.sail,.30.name=RAY.sail,.31.name=WILL.sail,.32.name=PRISCILLA,.33.name=RACHELS,.34.name=JEN,.35.name=OS1,.36.name=OS2,.37.name=unusedos,.38.name=VOX.fr.ext,.39.name=INS.fr.ext,.40.name=pass.fr.w2,
A12: {=IF(INDEX(CUEs!$A:$A,INT((ROW()-1)/7)*57+MOD(ROW()-1,7)+50)<>"","set "&INDEX(CUEs!$A:$A,INT((ROW()-1)/7)*57+MOD(ROW()-1,7)+50)&"=/ s "&INDEX(CUEs!$B:$B,INT((ROW()-1)/7)*57+MOD(ROW()-1,7)+50),"")} -> set w1_0002_ch_postins_a=/ s /ch.1.postins.on=1,mode=AUTO_X,..2.postins.on=1,mode=AUTO_X,..3.postins.on=1,mode=AUTO_X,..4.postins.on=0,mode=FX,..5.postins.on=1,mode=AUTO_X,..6.postins.on=1,mode=AUTO_X,..7.postins.on=1,mode=AUTO_X,..8.postins.on=1,mode=AUTO_X,..9.postins.on=1,mode=AUTO_X,..10.postins.on=1,mode=AUTO_X,..11.postins.on=1,mode=AUTO_X,..12.postins.on=1,mode=AUTO_X,..13.postins.on=1,mode=AUTO_Y,..14.postins.on=1,mode=AUTO_Y,..15.postins.on=1,mode=AUTO_Y,..16.postins.on=1,mode=AUTO_Y,..17.postins.on=0,mode=FX,..18.postins.on=0,mode=FX,..19.postins.on=0,mode=FX,..20.postins.on=0,mode=FX,
... A6500: {=IF(INDEX(CUEs!$A:$A,INT((ROW()-1)/7)*57+MOD(ROW()-1,7)+50)<>"","set "&INDEX(CUEs!$A:$A,INT((ROW()-1)/7)*57+MOD(ROW()-1,7)+50)&"=/ s "&INDEX(CUEs!$B:$B,INT((ROW()-1)/7)*57+MOD(ROW()-1,7)+50),"")}

Sheet README
A1: Overview
A4: To use this sheet in a CUE the cue file needs to reference the strings this sheet creates. These strings are in the EXPORT tab.
A5: Ideally, copy the content of EXPORT and use NOTEPAD and paste the content there. Then save that as a file in the folder where your CUEs are.
A6: The Export tab has about 4000 rows populated with formulas. But if you need more, just copy and paste from prior row(s) in that same tab as needed.
A8: In the Build_Variable_From_File.cmd file follow the instructions and use the file name you saved in the code you edit in that file.
A11: Then in the CUE enter the following but instead of "WING1" use the reference you set up for the mixer in the Build_Device_Types.cmd file for the target mixer and use the cell D2 (etc.) value insead of "w1_001" value:
A12: WING1|VARIABLEFROMFILE|w1_0001_ch_col_mute|
A13: WING1|VARIABLEFROMFILE|w1_0001_ch_tags|
A14: WING1|VARIABLEFROMFILE|w1_0001_ch_names_a|
A15: WING1|VARIABLEFROMFILE|w1_0001_ch_names_b|
A16: WING1|VARIABLEFROMFILE|w1_0001_ch_postins_a|
A17: WING1|VARIABLEFROMFILE|w1_0001_ch_postins_b|
... A57: That's about it!

Sheet Change Log
A1: 20261026a
A2: Split the names OSC into 2 lines because it was possible for the OSC string to exceed the 1024 character limit
A3: Names now use these lines:
A4: WING1|VARIABLEFROMFILE|w1_0001_ch_names_a|
A5: WING1|VARIABLEFROMFILE|w1_0001_ch_names_b|
A7: 20261016b
A8: Initial Release

Sheet refs
A1: COLORS
A2: MediumB | B2: 1
A3: BrightB | B3: 2
A4: Violet | B4: 3
A5: Turquoise | B5: 4
A6: Green | B6: 5
A7: OliveG | B7: 6
A8: Yellow | B8: 7
A9: Brown | B9: 8
A10: Red | B10: 9
A11: Coral | B11: 10
A12: Pink | B12: 11
A13: DarkV | B13: 12
... A19: White | B19: 18
A21: POSTINS
A22: FX
A23: AUTO_X
A24: AUTO_Y
