Workbook

Sheet USE THIS
A1: v20260327a | C1: =COUNTA(C2:C200) -> 73 | D1: First Connection | F1: PATH Part 1 | H1: formula | J1: PATH Part 2 | L1: formula | M1: Final to MIX | N1: VBM
D2: X32.out.BUS.01->UNET.13 | E2: ="->" -> -> | F2: X32.out.B.45 | G2: ="=" -> = | H2: ="WR1.in."&MID(F2,9,4) -> WR1.in.B.45 | M2: WR1.CH.01 | N2: =IF(MID(M2,1,3)="X32",VALUE(MID(M2,8,2)+96), IF(MID(M2,1,3)="WR1",VALUE(MID(M2,8,2)+0), IF(MID(M2,1,3)="WR2",VALUE(MID(M2,8,2)+48),"."))) -> 1
D3: X32.out.BUS.02->UNET.14 | E3: ="->" -> -> | F3: X32.out.B.46 | G3: ="=" -> = | H3: ="WR1.in."&MID(F3,9,4) -> WR1.in.B.46 | M3: WR1.CH.02 | N3: =IF(MID(M3,1,3)="X32",VALUE(MID(M3,8,2)+96), IF(MID(M3,1,3)="WR1",VALUE(MID(M3,8,2)+0), IF(MID(M3,1,3)="WR2",VALUE(MID(M3,8,2)+48),"."))) -> 2
D4: X32.out.BUS.03->UNET.15 | E4: ="->" -> -> | F4: X32.out.B.47 | G4: ="=" -> = | H4: ="WR1.in."&MID(F4,9,4) -> WR1.in.B.47 | M4: WR1.CH.03 | N4: =IF(MID(M4,1,3)="X32",VALUE(MID(M4,8,2)+96), IF(MID(M4,1,3)="WR1",VALUE(MID(M4,8,2)+0), IF(MID(M4,1,3)="WR2",VALUE(MID(M4,8,2)+48),"."))) -> 3
D5: X32.out.BUS.04->UNET.16 | E5: ="->" -> -> | F5: X32.out.B.48 | G5: ="=" -> = | H5: ="WR1.in."&MID(F5,9,4) -> WR1.in.B.48 | M5: WR1.CH.04 | N5: =IF(MID(M5,1,3)="X32",VALUE(MID(M5,8,2)+96), IF(MID(M5,1,3)="WR1",VALUE(MID(M5,8,2)+0), IF(MID(M5,1,3)="WR2",VALUE(MID(M5,8,2)+48),"."))) -> 4
A6: SLX.14 | B6: Pr Jeff | C6: Spoken.01 | D6: X32.in.LCL.01 | E6: ="->" -> -> | F6: X32.BUS.01 | M6: X32.CH.01 | N6: =IF(MID(M6,1,3)="X32",VALUE(MID(M6,8,2)+96), IF(MID(M6,1,3)="WR1",VALUE(MID(M6,8,2)+0), IF(MID(M6,1,3)="WR2",VALUE(MID(M6,8,2)+48),"."))) -> 97
A7: SLX.07 | B7: Vicar | C7: Spoken.02 | D7: X32.in.LCL.02 | E7: ="->" -> -> | F7: X32.BUS.01 | M7: X32.CH.02 | N7: =IF(MID(M7,1,3)="X32",VALUE(MID(M7,8,2)+96), IF(MID(M7,1,3)="WR1",VALUE(MID(M7,8,2)+0), IF(MID(M7,1,3)="WR2",VALUE(MID(M7,8,2)+48),"."))) -> 98
A8: SLX.08 | B8: Pr Paul | C8: Spoken.03 | D8: X32.in.LCL.03 | E8: ="->" -> -> | F8: X32.BUS.01 | M8: X32.CH.03 | N8: =IF(MID(M8,1,3)="X32",VALUE(MID(M8,8,2)+96), IF(MID(M8,1,3)="WR1",VALUE(MID(M8,8,2)+0), IF(MID(M8,1,3)="WR2",VALUE(MID(M8,8,2)+48),"."))) -> 99
A9: SLX.10 | B9: Kenzie | C9: Spoken.04 | D9: X32.in.LCL.04 | E9: ="->" -> -> | F9: X32.BUS.01 | M9: X32.CH.04 | N9: =IF(MID(M9,1,3)="X32",VALUE(MID(M9,8,2)+96), IF(MID(M9,1,3)="WR1",VALUE(MID(M9,8,2)+0), IF(MID(M9,1,3)="WR2",VALUE(MID(M9,8,2)+48),"."))) -> 100
A10: SLX.09 | B10: Guest.01 | C10: Spoken.05 | D10: X32.in.LCL.05 | E10: ="->" -> -> | F10: X32.BUS.01 | M10: X32.CH.05 | N10: =IF(MID(M10,1,3)="X32",VALUE(MID(M10,8,2)+96), IF(MID(M10,1,3)="WR1",VALUE(MID(M10,8,2)+0), IF(MID(M10,1,3)="WR2",VALUE(MID(M10,8,2)+48),"."))) -> 101
A11: SLX.15 | B11: Guest.02 | C11: Spoken.06 | D11: X32.in.LCL.06 | E11: ="->" -> -> | F11: X32.BUS.01 | M11: X32.CH.06 | N11: =IF(MID(M11,1,3)="X32",VALUE(MID(M11,8,2)+96), IF(MID(M11,1,3)="WR1",VALUE(MID(M11,8,2)+0), IF(MID(M11,1,3)="WR2",VALUE(MID(M11,8,2)+48),"."))) -> 102
A12: SLX.11 | B12: Guest.03 | C12: Annabell Violin Gst3 | D12: X32.in.LCL.07 | E12: ="->" -> -> | F12: X32.BUS.02 | M12: X32.CH.07 | N12: =IF(MID(M12,1,3)="X32",VALUE(MID(M12,8,2)+96), IF(MID(M12,1,3)="WR1",VALUE(MID(M12,8,2)+0), IF(MID(M12,1,3)="WR2",VALUE(MID(M12,8,2)+48),"."))) -> 103
D13: X32.in.LCL.08 | N13: =IF(MID(M13,1,3)="X32",VALUE(MID(M13,8,2)+96), IF(MID(M13,1,3)="WR1",VALUE(MID(M13,8,2)+0), IF(MID(M13,1,3)="WR2",VALUE(MID(M13,8,2)+48),"."))) -> .
D14: X32.in.LCL.09 | N14: =IF(MID(M14,1,3)="X32",VALUE(MID(M14,8,2)+96), IF(MID(M14,1,3)="WR1",VALUE(MID(M14,8,2)+0), IF(MID(M14,1,3)="WR2",VALUE(MID(M14,8,2)+48),"."))) -> .
A15: ULX.05 | B15: REWIRE | D15: X32.in.LCL.10 | N15: =IF(MID(M15,1,3)="X32",VALUE(MID(M15,8,2)+96), IF(MID(M15,1,3)="WR1",VALUE(MID(M15,8,2)+0), IF(MID(M15,1,3)="WR2",VALUE(MID(M15,8,2)+48),"."))) -> .
A16: SLX.12 | B16: Altar HH | C16: Altar HH | D16: X32.in.LCL.11 | M16: X32.CH.08 | N16: =IF(MID(M16,1,3)="X32",VALUE(MID(M16,8,2)+96), IF(MID(M16,1,3)="WR1",VALUE(MID(M16,8,2)+0), IF(MID(M16,1,3)="WR2",VALUE(MID(M16,8,2)+48),"."))) -> 104
A17: ULX.06 | B17: REWIRE | D17: X32.in.LCL.12 | N17: =IF(MID(M17,1,3)="X32",VALUE(MID(M17,8,2)+96), IF(MID(M17,1,3)="WR1",VALUE(MID(M17,8,2)+0), IF(MID(M17,1,3)="WR2",VALUE(MID(M17,8,2)+48),"."))) -> .
A18: SLX.16 | D18: X32.in.LCL.13 | N18: =IF(MID(M18,1,3)="X32",VALUE(MID(M18,8,2)+96), IF(MID(M18,1,3)="WR1",VALUE(MID(M18,8,2)+0), IF(MID(M18,1,3)="WR2",VALUE(MID(M18,8,2)+48),"."))) -> .
A19: SLX.18 | D19: X32.in.LCL.14 | N19: =IF(MID(M19,1,3)="X32",VALUE(MID(M19,8,2)+96), IF(MID(M19,1,3)="WR1",VALUE(MID(M19,8,2)+0), IF(MID(M19,1,3)="WR2",VALUE(MID(M19,8,2)+48),"."))) -> .
A20: HS.25 | B20: Hang.01 | C20: Organ | D20: X32.in.LCL.15 | M20: X32.CH.15 | N20: =IF(MID(M20,1,3)="X32",VALUE(MID(M20,8,2)+96), IF(MID(M20,1,3)="WR1",VALUE(MID(M20,8,2)+0), IF(MID(M20,1,3)="WR2",VALUE(MID(M20,8,2)+48),"."))) -> 111
A21: HS.29 | B21: Hang.03 | C21: Room | D21: X32.in.LCL.16 | M21: X32.CH.16 | N21: =IF(MID(M21,1,3)="X32",VALUE(MID(M21,8,2)+96), IF(MID(M21,1,3)="WR1",VALUE(MID(M21,8,2)+0), IF(MID(M21,1,3)="WR2",VALUE(MID(M21,8,2)+48),"."))) -> 112
A22: SLS.01->HS.18 | B22: SLS.01 | D22: X32.in.LCL.17 | N22: =IF(MID(M22,1,3)="X32",VALUE(MID(M22,8,2)+96), IF(MID(M22,1,3)="WR1",VALUE(MID(M22,8,2)+0), IF(MID(M22,1,3)="WR2",VALUE(MID(M22,8,2)+48),"."))) -> .
D23: X32.in.LCL.18 | N23: =IF(MID(M23,1,3)="X32",VALUE(MID(M23,8,2)+96), IF(MID(M23,1,3)="WR1",VALUE(MID(M23,8,2)+0), IF(MID(M23,1,3)="WR2",VALUE(MID(M23,8,2)+48),"."))) -> .
A24: SEN.06->SLS.02->HS.31 | B24: REWIRE | D24: X32.in.LCL.19 | N24: =IF(MID(M24,1,3)="X32",VALUE(MID(M24,8,2)+96), IF(MID(M24,1,3)="WR1",VALUE(MID(M24,8,2)+0), IF(MID(M24,1,3)="WR2",VALUE(MID(M24,8,2)+48),"."))) -> .
A25: SEN.07->SLS.03->HS.32 | B25: REWIRE | D25: X32.in.LCL.20 | N25: =IF(MID(M25,1,3)="X32",VALUE(MID(M25,8,2)+96), IF(MID(M25,1,3)="WR1",VALUE(MID(M25,8,2)+0), IF(MID(M25,1,3)="WR2",VALUE(MID(M25,8,2)+48),"."))) -> .
A26: SEN.08->SLS-04->HS.33 | B26: REWIRE | D26: X32.in.LCL.21 | N26: =IF(MID(M26,1,3)="X32",VALUE(MID(M26,8,2)+96), IF(MID(M26,1,3)="WR1",VALUE(MID(M26,8,2)+0), IF(MID(M26,1,3)="WR2",VALUE(MID(M26,8,2)+48),"."))) -> .
A27: SEN.09->SLS-05->HS.34 | B27: REWIRE | D27: X32.in.LCL.22 | N27: =IF(MID(M27,1,3)="X32",VALUE(MID(M27,8,2)+96), IF(MID(M27,1,3)="WR1",VALUE(MID(M27,8,2)+0), IF(MID(M27,1,3)="WR2",VALUE(MID(M27,8,2)+48),"."))) -> .
A28: SEN.10->SLS.06->HS.35 | B28: REWIRE | D28: X32.in.LCL.23 | N28: =IF(MID(M28,1,3)="X32",VALUE(MID(M28,8,2)+96), IF(MID(M28,1,3)="WR1",VALUE(MID(M28,8,2)+0), IF(MID(M28,1,3)="WR2",VALUE(MID(M28,8,2)+48),"."))) -> .
A29: SLS.07->HS.36 | D29: X32.in.LCL.24 | N29: =IF(MID(M29,1,3)="X32",VALUE(MID(M29,8,2)+96), IF(MID(M29,1,3)="WR1",VALUE(MID(M29,8,2)+0), IF(MID(M29,1,3)="WR2",VALUE(MID(M29,8,2)+48),"."))) -> .
A30: SLS.08->HS.09 | D30: X32.in.LCL.25 | N30: =IF(MID(M30,1,3)="X32",VALUE(MID(M30,8,2)+96), IF(MID(M30,1,3)="WR1",VALUE(MID(M30,8,2)+0), IF(MID(M30,1,3)="WR2",VALUE(MID(M30,8,2)+48),"."))) -> .
D31: X32.in.LCL.26 | N31: =IF(MID(M31,1,3)="X32",VALUE(MID(M31,8,2)+96), IF(MID(M31,1,3)="WR1",VALUE(MID(M31,8,2)+0), IF(MID(M31,1,3)="WR2",VALUE(MID(M31,8,2)+48),"."))) -> .
D32: X32.in.LCL.27 | N32: =IF(MID(M32,1,3)="X32",VALUE(MID(M32,8,2)+96), IF(MID(M32,1,3)="WR1",VALUE(MID(M32,8,2)+0), IF(MID(M32,1,3)="WR2",VALUE(MID(M32,8,2)+48),"."))) -> .
D33: X32.in.LCL.28 | N33: =IF(MID(M33,1,3)="X32",VALUE(MID(M33,8,2)+96), IF(MID(M33,1,3)="WR1",VALUE(MID(M33,8,2)+0), IF(MID(M33,1,3)="WR2",VALUE(MID(M33,8,2)+48),"."))) -> .
D34: X32.in.LCL.29 | N34: =IF(MID(M34,1,3)="X32",VALUE(MID(M34,8,2)+96), IF(MID(M34,1,3)="WR1",VALUE(MID(M34,8,2)+0), IF(MID(M34,1,3)="WR2",VALUE(MID(M34,8,2)+48),"."))) -> .
D35: X32.in.LCL.30 | N35: =IF(MID(M35,1,3)="X32",VALUE(MID(M35,8,2)+96), IF(MID(M35,1,3)="WR1",VALUE(MID(M35,8,2)+0), IF(MID(M35,1,3)="WR2",VALUE(MID(M35,8,2)+48),"."))) -> .
D36: X32.in.LCL.31 | N36: =IF(MID(M36,1,3)="X32",VALUE(MID(M36,8,2)+96), IF(MID(M36,1,3)="WR1",VALUE(MID(M36,8,2)+0), IF(MID(M36,1,3)="WR2",VALUE(MID(M36,8,2)+48),"."))) -> .
D37: X32.in.LCL.32 | N37: =IF(MID(M37,1,3)="X32",VALUE(MID(M37,8,2)+96), IF(MID(M37,1,3)="WR1",VALUE(MID(M37,8,2)+0), IF(MID(M37,1,3)="WR2",VALUE(MID(M37,8,2)+48),"."))) -> .
A38: BT-L | D38: X32.in.AUX.01 | M38: X32.CH.27 | N38: =IF(MID(M38,1,3)="X32",VALUE(MID(M38,8,2)+96), IF(MID(M38,1,3)="WR1",VALUE(MID(M38,8,2)+0), IF(MID(M38,1,3)="WR2",VALUE(MID(M38,8,2)+48),"."))) -> 123
A39: BT-R | D39: X32.in.AUX.02 | M39: X32.CH.28 | N39: =IF(MID(M39,1,3)="X32",VALUE(MID(M39,8,2)+96), IF(MID(M39,1,3)="WR1",VALUE(MID(M39,8,2)+0), IF(MID(M39,1,3)="WR2",VALUE(MID(M39,8,2)+48),"."))) -> 124
A40: CD-L | D40: X32.in.AUX.03 | M40: X32.CH.29 | N40: =IF(MID(M40,1,3)="X32",VALUE(MID(M40,8,2)+96), IF(MID(M40,1,3)="WR1",VALUE(MID(M40,8,2)+0), IF(MID(M40,1,3)="WR2",VALUE(MID(M40,8,2)+48),"."))) -> 125
...

Sheet REFS
A1: notes | B1: NAME | C1: Device | D1: Cable | E1: patch | F1: CMX32 PATH IN | G1: CMX-W1 B | H1: WING1 PATH | I1: WING2 Path
D2: hs.01 | E2: srs.01
D3: hs.02 | E3: bad?
D4: hs.03 | E4: bad?
D5: hs.04 | E5: srs.02
D6: hs.05 | E6: srs.03
D7: hs.06 | E7: srs.04
D8: hs.07 | E8: srs.05
D9: hs.08 | E9: srs.06
D10: hs.09 | E10: sls.08 | F10: cmx.L.in.25
D11: hs.10 | E11: bad?
A12: reconnect from cmx.L.in.26 to wing2 | B12: Timpani1 | D12: hs.11 | E12: sls.09 | F12: w2.L.in.01
A13: reconnect from cmx.L.in.27 to wing 2 | B13: Timpani2 | D13: hs.12 | E13: sls.10 | F13: w2.L.in.02
A14: reconnect from cmx.L.in.28 to wing 2 | B14: Timpani3 | D14: hs.13 | E14: sls.11 | F14: w2.L.in.03
A15: reconnect from cmx.L.in.29 to wing 2 | B15: Timpani4 | D15: hs.14 | E15: sls.12 | F15: w2.L.in.04
C16: bad | D16: hs.15 | E16: sls.15
D17: hs.16 | E17: sls.13 | F17: cmx.L.in.30
D18: hs.17 | E18: sls.14 | F18: cmx.L.in.31
B19: SEN.hh.11 | C19: SEN.11 | D19: hs.18 | E19: sls.01 | F19: cmx.L.in.17
D20: hs.19 | E20: srs.07
D21: hs.20 | E21: srs.08
D22: hs.21 | E22: srs.09
D23: hs.22 | E23: srs.10
D24: hs.23 | E24: srs.11
D25: hs.24 | E25: srs.12
B26: Organ | C26: hangmic.01 | D26: hs.25 | E26: hang.01 | F26: cmx.L.in.15
D27: hs.26 | E27: srs.13
D28: hs.27 | E28: srs.14
D29: hs.28 | E29: srs.15
B30: Room | C30: hangmic.03 | D30: hs.29 | E30: hang.03 | F30: cmx.L.in.16
D31: hs.30 | E31: sls.15 | F31: cmx.L.in.32
B32: SEN.hh.12 | C32: SEN.12 | D32: hs.31 | E32: sls.02 | F32: cmx.L.in.19
A33: wire up | B33: SEN.06 | C33: SEN.06 | D33: hs.32 | E33: sls.03 | F33: cmx.L.in.20
A34: wire up | B34: SEN.07 | C34: SEN.07 | D34: hs.33 | E34: sls.04 | F34: cmx.L.in.21
A35: wire up | B35: SEN.08 | C35: SEN.08 | D35: hs.34 | E35: sls.05 | F35: cmx.L.in.22
A36: wire up | B36: SEN.09 | C36: SEN.09 | D36: hs.35 | E36: sls.06 | F36: cmx.L.in.23
A37: wire up | B37: SEN.10 | C37: SEN.10 | D37: hs.36 | E37: sls.07 | F37: cmx.L.in.24
B38: Pr Jeff | C38: SLX.14 | D38: dir.slx.14 | F38: cmx.L.in.01
B39: Vicar | C39: SLX.07 | D39: dir.slx.07 | F39: cmx.L.in.02
B40: Pr Paul | C40: SLX.08 | D40: dir.slx.08 | F40: cmx.L.in.03
...

Sheet Sheet1
A1: ITEM 20260226a | B1: Input for Source | C1: Exposed on or out from CM X32 | F1: Into WING Rack 1 | G1: Exposed on or Out from Wing Rack 1 | H1: Into Wing Rack 2 | I1: Exposed on | J1: Out to Reaper from | K1: to Reaper Device | L1: VB In | M1: Reaper Input Number
A2: PIANO | B2: CMX32.DL16.1.01-A.01 | C2: CMX32.usrout.01 | E2: CMX32.B.01 | F2: LJWINGR.B.01 | G2: LJWINGR.C.07 | H2: LJX32R.A.07 | I2: LJX32R.CH.01 | J2: LJX32R.B.01 | K2: KT9630 | L2: VB.KT.01 | M2: RPR.49
A3: Annabelle Violin/MG eBG | B3: CMX32.DL16.1.03-A.03 | C3: CMX32.usrout.02 | E3: CMX32.B.02 | F3: LJWINGR.B.02 | G3: LJWINGR.C.08 | H3: LJX32R.A.08 | I3: LJX32R.CH.02 | J3: LJX32R.B.02 | K3: KT9630 | L3: VB.KT.02 | M3: RPR.50
A4: Maddie Flute/MG EG | B4: CMX32.DL16.1.04-A.04 | C4: CMX32.usrout.03 | E4: CMX32.B.03 | F4: LJWINGR.B.03 | G4: LJWINGR.C.09 | H4: LJX32R.A.09 | I4: LJX32R.CH.03 | J4: LJX32R.B.03 | K4: KT9630 | L4: VB.KT.03 | M4: RPR.51
A5: MG AG | B5: CMX32.DL16.1.06-A.06 | C5: CMX32.usrout.04 | E5: CMX32.B.04 | F5: LJWINGR.B.04 | G5: LJWINGR.C.10 | H5: LJX32R.A.10 | I5: LJX32R.CH.04 | J5: LJX32R.B.04 | K5: KT9630 | L5: VB.KT.04 | M5: RPR.52
A6: MG KICK | B6: CMX32.DL16.1.07-A.07 | C6: CMX32.usrout.05 | E6: CMX32.B.05 | F6: LJWINGR.B.05 | G6: LJWINGR.C.11 | H6: LJX32R.A.11 | I6: LJX32R.CH.05 | J6: LJX32R.B.05 | K6: KT9630 | L6: VB.KT.05 | M6: RPR.53
A7: MG SNARE | B7: CMX32.DL16.1.08-A.08 | C7: CMX32.usrout.06 | E7: CMX32.B.06 | F7: LJWINGR.B.06 | G7: LJWINGR.C.12 | H7: LJX32R.A.12 | I7: LJX32R.CH.06 | J7: LJX32R.B.06 | K7: KT9630 | L7: VB.KT.06 | M7: RPR.54
A8: MG OHL | B8: CMX32.DL16.1.09-A.09 | C8: CMX32.usrout.07 | E8: CMX32.B.07 | F8: LJWINGR.B.07 | G8: LJWINGR.C.13 | H8: LJX32R.A.13 | I8: LJX32R.CH.07 | J8: LJX32R.B.07 | K8: KT9630 | L8: VB.KT.07 | M8: RPR.55
A9: MG OHR | B9: CMX32.DL16.1.10-A.10 | C9: CMX32.usrout.08 | E9: CMX32.B.08 | F9: LJWINGR.B.08 | G9: LJWINGR.C.14 | H9: LJX32R.A.14 | I9: LJX32R.CH.08 | J9: LJX32R.B.08 | K9: KT9630 | L9: VB.KT.08 | M9: RPR.56
A10: percussion 1/MG PAD | B10: CMX32.DL16.2.11-A.27 | C10: CMX32.usrout.09 | E10: CMX32.B.09 | F10: LJWINGR.B.09 | G10: LJWINGR.C.15 | H10: LJX32R.A.15 | I10: LJX32R.CH.12 | J10: LJX32R.B.12 | K10: KT9630 | L10: VB.KT.12 | M10: RPR.57
A11: bone 1 | B11: CMX32.DL16.2.13-A.29 | C11: CMX32.usrout.10 | E11: CMX32.B.10 | F11: LJWINGR.B.10 | G11: LJWINGR.C.16 | H11: LJX32R.A.16 | I11: LJX32R.CH.14 | J11: LJX32R.B.14 | K11: KT9630 | L11: VB.KT.14 | M11: RPR.58
A12: bone 2 | B12: CMX32.DL16.2.14-A.30 | C12: CMX32.usrout.11 | E12: CMX32.B.11 | F12: LJWINGR.B.11 | G12: LJWINGR.C.17 | H12: LJX32R.A.17 | I12: LJX32R.CH.15 | J12: LJX32R.B.15 | K12: KT9630 | L12: VB.KT.15 | M12: RPR.59
A13: tuba | B13: CMX32.DL16.2.15-A.31 | C13: CMX32.usrout.12 | E13: CMX32.B.12 | F13: LJWINGR.B.12 | G13: LJWINGR.C.18 | H13: LJX32R.A.18 | I13: LJX32R.CH.16 | J13: LJX32R.B.16 | K13: KT9630 | L13: VB.KT.16 | M13: RPR.60
... A26: violin 2 | B26: CMX32.DL16.3.15-A.47 | C26: CMX32.usrout.24 | E26: CMX32.B.24 | F26: LJWINGR.B.24 | G26: LJWINGR.C.30 | H26: LJX32R.A.30 | I26: LJX32R.CH.29 | J26: LJX32R.B.29 | K26: KT9630 | L26: VB.KT.29 | M26: RPR.73
A27: standing bass sls.13(16) | H27: LJX32R.LCL.01 | I27: LJX32R.CH.30 | J27: LJX32R.B.30 | K27: KT9630 | L27: VB.KT.30 | M27: RPR.74
A28: cello | B28: CMX32.DL16.3.01-A.33 | C28: CMX32.usrout.47 | E28: CMX32.B.47 | F28: LJWINGR.B.47 | G28: LJWINGR.C.32 | H28: LJX32R.A.32 | I28: LJX32R.CH.31 | J28: LJX32R.B.31 | K28: KT9630 | L28: VB.KT.31 | M28: RPR.75
A29: gregg tracks | B29: CMX32.DL16.3.16-A.48 | C29: CMX32.usrout.25 | E29: CMX32.B.25 | F29: LJWINGR.B.25 | G29: LJWINGR.C.31 | H29: LJX32R.A.31 | I29: LJX32R.CH.32 | J29: LJX32R.B.32 | K29: KT9630 | L29: VB.KT.32 | M29: RPR.76
A30: timpani 1 | B30: CMX32.DL16.1.02-A.02 | C30: CMX32.usrout.26 | E30: CMX32.B.26 | F30: LJWINGR.B.26 | G30: LJWINGR.CH.33 | J30: LJWINGR.USB.33 | K30: wUSB | L30: VB.USB.33 | M30: RPR.33
A31: timpani 2 | B31: CMX32.DL16.1.05-A.05 | C31: CMX32.usrout.27 | E31: CMX32.B.27 | F31: LJWINGR.B.27 | G31: LJWINGR.CH.34 | J31: LJWINGR.USB.34 | K31: wUSB | L31: VB.USB.34 | M31: RPR.34
A32: timpani 3/MG TOM 1 | B32: CMX32.DL16.2.09-A.25 | C32: CMX32.usrout.28 | E32: CMX32.B.28 | F32: LJWINGR.B.28 | G32: LJWINGR.CH.35 | J32: LJWINGR.USB.35 | K32: wUSB | L32: VB.USB.35 | M32: RPR.35
A33: timpani 4/MG TOM 2 | B33: CMX32.DL16.2.10-A.26 | C33: CMX32.usrout.29 | E33: CMX32.B.29 | F33: LJWINGR.B.29 | G33: LJWINGR.CH.36 | J33: LJWINGR.USB.36 | K33: wUSB | L33: VB.USB.36 | M33: RPR.36
A34: Choir 1 | B34: CMX32.DL16.2.01-A.17 | C34: CMX32.usrout.30 | E34: CMX32.B.30 | F34: LJWINGR.B.30 | G34: LJWINGR.CH.01 | J34: LJWINGR.USB.01 | K34: wUSB | L34: VB.USB.01 | M34: RPR.01
A35: Choir 2 | B35: CMX32.DL16.2.02-A.18 | C35: CMX32.usrout.31 | E35: CMX32.B.31 | F35: LJWINGR.B.31 | G35: LJWINGR.CH.02 | J35: LJWINGR.USB.02 | K35: wUSB | L35: VB.USB.02 | M35: RPR.02
A36: Choir 3 | B36: CMX32.DL16.2.03-A.19 | C36: CMX32.usrout.32 | E36: CMX32.B.32 | F36: LJWINGR.B.32 | G36: LJWINGR.CH.03 | J36: LJWINGR.USB.03 | K36: wUSB | L36: VB.USB.03 | M36: RPR.03
A37: Choir 4 | B37: CMX32.DL16.2.04-A.20 | C37: CMX32.usrout.33 | E37: CMX32.B.33 | F37: LJWINGR.B.33 | G37: LJWINGR.CH.04 | J37: LJWINGR.USB.04 | K37: wUSB | L37: VB.USB.04 | M37: RPR.04
A38: Choir 5 | B38: CMX32.DL16.2.05-A.21 | C38: CMX32.usrout.34 | E38: CMX32.B.34 | F38: LJWINGR.B.34 | G38: LJWINGR.CH.05 | J38: LJWINGR.USB.05 | K38: wUSB | L38: VB.USB.05 | M38: RPR.05
A39: Choir 6 | B39: CMX32.DL16.2.06-A.22 | C39: CMX32.usrout.35 | E39: CMX32.B.35 | F39: LJWINGR.B.35 | G39: LJWINGR.CH.06 | J39: LJWINGR.USB.06 | K39: wUSB | L39: VB.USB.06 | M39: RPR.06
A40: Choir 7 | B40: CMX32.DL16.2.07-A.23 | C40: CMX32.usrout.36 | E40: CMX32.B.36 | F40: LJWINGR.B.36 | G40: LJWINGR.CH.07 | J40: LJWINGR.USB.07 | K40: wUSB | L40: VB.USB.07 | M40: RPR.07
A41: Choir 8 | B41: CMX32.DL16.2.08-A.24 | C41: CMX32.usrout.37 | E41: CMX32.B.37 | F41: LJWINGR.B.37 | G41: LJWINGR.CH.08 | J41: LJWINGR.USB.08 | K41: wUSB | L41: VB.USB.08 | M41: RPR.08
... A45: sing 4 | B45: CMX32.DL16.1.15-A.15 | C45: CMX32.usrout.41 | E45: CMX32.B.41 | F45: LJWINGR.B.41 | G45: LJWINGR.CH.12 | J45: LJWINGR.USB.12 | K45: wUSB | L45: VB.USB.12 | M45: RPR.12
A46: ="@Piano mic" -> @Piano mic | B46: CMX32.DL16.1.16-A.16 | C46: CMX32.usrout.42 | E46: CMX32.B.42 | F46: LJWINGR.B.42 | G46: LJWINGR.CH.13 | J46: LJWINGR.USB.13 | K46: wUSB | L46: VB.USB.13 | M46: RPR.13
A47: SEN.01 skit JOCELYN sls.03(32) rewire | F47: LJWINGR.LCL.01 | G47: LJWINGR.CH.15 | J47: LJWINGR.USB.15 | K47: wUSB | L47: VB.USB.15 | M47: RPR.15
A48: SEN.02 skit CHLOE sls.04(33) rewire | F48: LJWINGR.LCL.02 | G48: LJWINGR.CH.16 | J48: LJWINGR.USB.16 | K48: wUSB | L48: VB.USB.16 | M48: RPR.16
A49: SEN.03 skit STELLA sls.05(34) rewire | F49: LJWINGR.LCL.03 | G49: LJWINGR.CH.17 | J49: LJWINGR.USB.17 | K49: wUSB | L49: VB.USB.17 | M49: RPR.17
A50: SEN.04 skit CARSON sls.06(35) rewire | F50: LJWINGR.LCL.04 | G50: LJWINGR.CH.18 | J50: LJWINGR.USB.18 | K50: wUSB | L50: VB.USB.18 | M50: RPR.18
A51: SEN.05 skit KIRBY sls.07(36) rewire | F51: LJWINGR.LCL.05 | G51: LJWINGR.CH.19 | J51: LJWINGR.USB.19 | K51: wUSB | L51: VB.USB.19 | M51: RPR.19
A52: SEN.05 skit ANNABELLE sls.08(09) rewire | F52: LJWINGR.LCL.06 | G52: LJWINGR.CH.20 | J52: LJWINGR.USB.20 | K52: wUSB | L52: VB.USB.20 | M52: RPR.20
A53: CMX32.BUS.01 PASTORs | B53: grp1 | C53: CMX32.usrout.45 | E53: CMX32.B.45 | F53: LJWINGR.B.43 | G53: LJWINGR.CH.21 | J53: LJWINGR.USB.21 | K53: wUSB | L53: VB.USB.21 | M53: RPR.21
A54: CMX32.BUS.02 PKs | B54: grp2 | C54: CMX32.usrout.46 | E54: CMX32.B.46 | F54: LJWINGR.B.44 | G54: LJWINGR.CH.22 | J54: LJWINGR.USB.22 | K54: wUSB | L54: VB.USB.22 | M54: RPR.22
A55: CMX32.BUS.03 SEN Vox | B55: grp3 | C55: CMX32.usrout.47 | E55: CMX32.B.47 | F55: LJWINGR.B.45 | G55: LJWINGR.CH.23 | J55: LJWINGR.USB.23 | K55: wUSB | L55: VB.USB.23 | M55: RPR.23
...

Sheet Sheet2
E1: 20260306a INFO | G1: CM X32 | J1: CH#=usrin# out B= usrout | K1: VBM fr uin/ crd out | M1: WING 1 | P1: VBM | R1: WING 2 | U1: VBM
A2: in | F2: =">" -> > | G2: BUS.01 UNET.13 | H2: Group 1 | J2: B.out.45 | K2: =IF(MID(G2,1,3)="CH.",VALUE(MID(G2,4,2))+96,".") -> . | M2: =IF(MID(J2,1,6)="B.out.","B.in."&MID(J2,7,2),".") -> B.in.45 | N2: Group 1 | O2: CH.01 | P2: =IF(MID(O2,1,3)="CH.",VALUE(MID(O2,4,2))+0,".") -> 1 | R2: =IF(MID(O2,1,6)="C.out.","C.in."&MID(O2,7,2),".") -> . | S2: =IF(MID(T2,1,3)="CH.",$E2,"") | U2: =IF(MID(M2,1,3)="X32.",VALUE(MID(M2,8,2))+96, IF(MID(M2,1,3)="MR1.",VALUE(MID(M2,8,2))+0, IF(MID(M2,1,3)="MR2.",VALUE(MID(M2,8,2))+48,"."))) -> .
A3: in | F3: =">" -> > | G3: BUS.02 UNET.14 | H3: Group 2 | J3: B.out.46 | K3: =IF(MID(G3,1,3)="CH.",VALUE(MID(G3,4,2))+96,".") -> . | M3: =IF(MID(J3,1,6)="B.out.","B.in."&MID(J3,7,2),".") -> B.in.46 | N3: Group 2 | O3: CH.02 | P3: =IF(MID(O3,1,3)="CH.",VALUE(MID(O3,4,2))+0,".") -> 2 | R3: =IF(MID(O3,1,6)="C.out.","C.in."&MID(O3,7,2),".") -> . | S3: =IF(MID(T3,1,3)="CH.",$E3,"") | U3: =IF(MID(T3,1,3)="CH.",VALUE(MID(T3,4,2))+48,".") -> .
A4: in | F4: =">" -> > | G4: BUS.03 UNET.15 | H4: Group 3 | J4: B.out.47 | K4: =IF(MID(G4,1,3)="CH.",VALUE(MID(G4,4,2))+96,".") -> . | M4: =IF(MID(J4,1,6)="B.out.","B.in."&MID(J4,7,2),".") -> B.in.47 | N4: Group 3 | O4: CH.03 | P4: =IF(MID(O4,1,3)="CH.",VALUE(MID(O4,4,2))+0,".") -> 3 | R4: =IF(MID(O4,1,6)="C.out.","C.in."&MID(O4,7,2),".") -> . | S4: =IF(MID(T4,1,3)="CH.",$E4,"") | U4: =IF(MID(T4,1,3)="CH.",VALUE(MID(T4,4,2))+48,".") -> .
A5: in | F5: =">" -> > | G5: BUS.04 UNET.16 | H5: Group 4 | J5: B.out.48 | K5: =IF(MID(G5,1,3)="CH.",VALUE(MID(G5,4,2))+96,".") -> . | M5: =IF(MID(J5,1,6)="B.out.","B.in."&MID(J5,7,2),".") -> B.in.48 | N5: Group 4 | O5: CH.04 | P5: =IF(MID(O5,1,3)="CH.",VALUE(MID(O5,4,2))+0,".") -> 4 | R5: =IF(MID(O5,1,6)="C.out.","C.in."&MID(O5,7,2),".") -> . | S5: =IF(MID(T5,1,3)="CH.",$E5,"") | U5: =IF(MID(T5,1,3)="CH.",VALUE(MID(T5,4,2))+48,".") -> .
A6: in | B6: SLX.14 | E6: Pr Jeff | F6: =">" -> > | G6: L.in.01 | H6: =IF(MID(J6,1,3)="CH.",$E6,"") -> Pr Jeff | I6: BUS.01 | J6: CH.01 | K6: =IF(MID(J6,1,3)="CH.",VALUE(MID(J6,4,2))+96,".") -> 97 | M6: =IF(MID(J6,1,6)="B.out.","B.in."&MID(J6,7,2),".") -> . | N6: =IF(MID(O6,1,3)="CH.",$E6,"") | P6: =IF(MID(O6,1,3)="CH.",VALUE(MID(O6,4,2))+0,".") -> . | R6: =IF(MID(O6,1,6)="C.out.","C.in."&MID(O6,7,2),".") -> . | S6: =IF(MID(T6,1,3)="CH.",$E6,"") | U6: =IF(MID(T6,1,3)="CH.",VALUE(MID(T6,4,2))+48,".") -> .
A7: in | B7: SLX.07 | E7: Vicar | F7: =">" -> > | G7: L.in.02 | H7: =IF(MID(J7,1,3)="CH.",$E7,"") -> Vicar | I7: BUS.01 | J7: CH.02 | K7: =IF(MID(J7,1,3)="CH.",VALUE(MID(J7,4,2))+96,".") -> 98 | M7: =IF(MID(J7,1,6)="B.out.","B.in."&MID(J7,7,2),".") -> . | N7: =IF(MID(O7,1,3)="CH.",$E7,"") | P7: =IF(MID(O7,1,3)="CH.",VALUE(MID(O7,4,2))+0,".") -> . | R7: =IF(MID(O7,1,6)="C.out.","C.in."&MID(O7,7,2),".") -> . | S7: =IF(MID(T7,1,3)="CH.",$E7,"") | U7: =IF(MID(T7,1,3)="CH.",VALUE(MID(T7,4,2))+48,".") -> .
A8: in | B8: SLX.08 | E8: Pr Paul | F8: =">" -> > | G8: L.in.03 | H8: =IF(MID(J8,1,3)="CH.",$E8,"") -> Pr Paul | I8: BUS.01 | J8: CH.03 | K8: =IF(MID(J8,1,3)="CH.",VALUE(MID(J8,4,2))+96,".") -> 99 | M8: =IF(MID(J8,1,6)="B.out.","B.in."&MID(J8,7,2),".") -> . | N8: =IF(MID(O8,1,3)="CH.",$E8,"") | P8: =IF(MID(O8,1,3)="CH.",VALUE(MID(O8,4,2))+0,".") -> . | R8: =IF(MID(O8,1,6)="C.out.","C.in."&MID(O8,7,2),".") -> . | S8: =IF(MID(T8,1,3)="CH.",$E8,"") | U8: =IF(MID(T8,1,3)="CH.",VALUE(MID(T8,4,2))+48,".") -> .
A9: in | B9: SLX.10 | E9: Kenzie | F9: =">" -> > | G9: L.in.04 | H9: =IF(MID(J9,1,3)="CH.",$E9,"") -> Kenzie | I9: BUS.01 | J9: CH.04 | K9: =IF(MID(J9,1,3)="CH.",VALUE(MID(J9,4,2))+96,".") -> 100 | M9: =IF(MID(J9,1,6)="B.out.","B.in."&MID(J9,7,2),".") -> . | N9: =IF(MID(O9,1,3)="CH.",$E9,"") | P9: =IF(MID(O9,1,3)="CH.",VALUE(MID(O9,4,2))+0,".") -> . | R9: =IF(MID(O9,1,6)="C.out.","C.in."&MID(O9,7,2),".") -> . | S9: =IF(MID(T9,1,3)="CH.",$E9,"") | U9: =IF(MID(T9,1,3)="CH.",VALUE(MID(T9,4,2))+48,".") -> .
A10: in | B10: SLX.09 | E10: GST 1 | F10: =">" -> > | G10: L.in.05 | H10: =IF(MID(J10,1,3)="CH.",$E10,"") -> GST 1 | I10: BUS.01 | J10: CH.05 | K10: =IF(MID(J10,1,3)="CH.",VALUE(MID(J10,4,2))+96,".") -> 101 | M10: =IF(MID(J10,1,6)="B.out.","B.in."&MID(J10,7,2),".") -> . | N10: =IF(MID(O10,1,3)="CH.",$E10,"") | P10: =IF(MID(O10,1,3)="CH.",VALUE(MID(O10,4,2))+0,".") -> . | R10: =IF(MID(O10,1,6)="C.out.","C.in."&MID(O10,7,2),".") -> . | S10: =IF(MID(T10,1,3)="CH.",$E10,"") | U10: =IF(MID(T10,1,3)="CH.",VALUE(MID(T10,4,2))+48,".") -> .
A11: in | B11: SLX.15 | E11: GST 2 | F11: =">" -> > | G11: L.in.06 | H11: =IF(MID(J11,1,3)="CH.",$E11,"") -> GST 2 | I11: BUS.01 | J11: CH.06 | K11: =IF(MID(J11,1,3)="CH.",VALUE(MID(J11,4,2))+96,".") -> 102 | M11: =IF(MID(J11,1,6)="B.out.","B.in."&MID(J11,7,2),".") -> . | N11: =IF(MID(O11,1,3)="CH.",$E11,"") | P11: =IF(MID(O11,1,3)="CH.",VALUE(MID(O11,4,2))+0,".") -> . | R11: =IF(MID(O11,1,6)="C.out.","C.in."&MID(O11,7,2),".") -> . | S11: =IF(MID(T11,1,3)="CH.",$E11,"") | U11: =IF(MID(T11,1,3)="CH.",VALUE(MID(T11,4,2))+48,".") -> .
A12: in | B12: SLX.11 | E12: GST 3 | F12: =">" -> > | G12: L.in.07 | H12: =IF(MID(J12,1,3)="CH.",$E12,"") -> GST 3 | I12: BUS.01 | J12: CH.07 | K12: =IF(MID(J12,1,3)="CH.",VALUE(MID(J12,4,2))+96,".") -> 103 | M12: =IF(MID(J12,1,6)="B.out.","B.in."&MID(J12,7,2),".") -> . | N12: =IF(MID(O12,1,3)="CH.",$E12,"") | P12: =IF(MID(O12,1,3)="CH.",VALUE(MID(O12,4,2))+0,".") -> . | R12: =IF(MID(O12,1,6)="C.out.","C.in."&MID(O12,7,2),".") -> . | S12: =IF(MID(T12,1,3)="CH.",$E12,"") | U12: =IF(MID(T12,1,3)="CH.",VALUE(MID(T12,4,2))+48,".") -> .
A13: in | F13: =">" -> > | G13: L.in.08 | H13: =IF(MID(J13,1,3)="CH.",$E13,"") | K13: =IF(MID(J13,1,3)="CH.",VALUE(MID(J13,4,2))+96,".") -> . | M13: =IF(MID(J13,1,6)="B.out.","B.in."&MID(J13,7,2),".") -> . | N13: =IF(MID(O13,1,3)="CH.",$E13,"") | P13: =IF(MID(O13,1,3)="CH.",VALUE(MID(O13,4,2))+0,".") -> . | R13: =IF(MID(O13,1,6)="C.out.","C.in."&MID(O13,7,2),".") -> . | S13: =IF(MID(T13,1,3)="CH.",$E13,"") | U13: =IF(MID(T13,1,3)="CH.",VALUE(MID(T13,4,2))+48,".") -> .
A14: in | F14: =">" -> > | G14: L.in.09 | H14: =IF(MID(J14,1,3)="CH.",$E14,"") | K14: =IF(MID(J14,1,3)="CH.",VALUE(MID(J14,4,2))+96,".") -> . | M14: =IF(MID(J14,1,6)="B.out.","B.in."&MID(J14,7,2),".") -> . | N14: =IF(MID(O14,1,3)="CH.",$E14,"") | P14: =IF(MID(O14,1,3)="CH.",VALUE(MID(O14,4,2))+0,".") -> . | R14: =IF(MID(O14,1,6)="C.out.","C.in."&MID(O14,7,2),".") -> . | S14: =IF(MID(T14,1,3)="CH.",$E14,"") | U14: =IF(MID(T14,1,3)="CH.",VALUE(MID(T14,4,2))+48,".") -> .
A15: in | B15: ULX.05 | F15: =">" -> > | G15: L.in.10 | H15: =IF(MID(J15,1,3)="CH.",$E15,"") | K15: =IF(MID(J15,1,3)="CH.",VALUE(MID(J15,4,2))+96,".") -> . | M15: =IF(MID(J15,1,6)="B.out.","B.in."&MID(J15,7,2),".") -> . | N15: =IF(MID(O15,1,3)="CH.",$E15,"") | P15: =IF(MID(O15,1,3)="CH.",VALUE(MID(O15,4,2))+0,".") -> . | R15: =IF(MID(O15,1,6)="C.out.","C.in."&MID(O15,7,2),".") -> . | S15: =IF(MID(T15,1,3)="CH.",$E15,"") | U15: =IF(MID(T15,1,3)="CH.",VALUE(MID(T15,4,2))+48,".") -> .
A16: in | B16: SLX.12 | E16: Altar | F16: =">" -> > | G16: L.in.11 | H16: =IF(MID(J16,1,3)="CH.",$E16,"") -> Altar | I16: BUS.01 | J16: CH.08 | K16: =IF(MID(J16,1,3)="CH.",VALUE(MID(J16,4,2))+96,".") -> 104 | M16: =IF(MID(J16,1,6)="B.out.","B.in."&MID(J16,7,2),".") -> . | N16: =IF(MID(O16,1,3)="CH.",$E16,"") | P16: =IF(MID(O16,1,3)="CH.",VALUE(MID(O16,4,2))+0,".") -> . | R16: =IF(MID(O16,1,6)="C.out.","C.in."&MID(O16,7,2),".") -> . | S16: =IF(MID(T16,1,3)="CH.",$E16,"") | U16: =IF(MID(T16,1,3)="CH.",VALUE(MID(T16,4,2))+48,".") -> .
A17: in | B17: ULX.06 | F17: =">" -> > | G17: L.in.12 | H17: =IF(MID(J17,1,3)="CH.",$E17,"") | K17: =IF(MID(J17,1,3)="CH.",VALUE(MID(J17,4,2))+96,".") -> . | M17: =IF(MID(J17,1,6)="B.out.","B.in."&MID(J17,7,2),".") -> . | N17: =IF(MID(O17,1,3)="CH.",$E17,"") | P17: =IF(MID(O17,1,3)="CH.",VALUE(MID(O17,4,2))+0,".") -> . | R17: =IF(MID(O17,1,6)="C.out.","C.in."&MID(O17,7,2),".") -> . | S17: =IF(MID(T17,1,3)="CH.",$E17,"") | U17: =IF(MID(T17,1,3)="CH.",VALUE(MID(T17,4,2))+48,".") -> .
A18: in | B18: SLX.16 | F18: =">" -> > | G18: L.in.13 | H18: =IF(MID(J18,1,3)="CH.",$E18,"") | K18: =IF(MID(J18,1,3)="CH.",VALUE(MID(J18,4,2))+96,".") -> . | M18: =IF(MID(J18,1,6)="B.out.","B.in."&MID(J18,7,2),".") -> . | N18: =IF(MID(O18,1,3)="CH.",$E18,"") | P18: =IF(MID(O18,1,3)="CH.",VALUE(MID(O18,4,2))+0,".") -> . | R18: =IF(MID(O18,1,6)="C.out.","C.in."&MID(O18,7,2),".") -> . | S18: =IF(MID(T18,1,3)="CH.",$E18,"") | U18: =IF(MID(T18,1,3)="CH.",VALUE(MID(T18,4,2))+48,".") -> .
A19: in | B19: SLX.18 | F19: =">" -> > | G19: L.in.14 | H19: =IF(MID(J19,1,3)="CH.",$E19,"") | K19: =IF(MID(J19,1,3)="CH.",VALUE(MID(J19,4,2))+96,".") -> . | M19: =IF(MID(J19,1,6)="B.out.","B.in."&MID(J19,7,2),".") -> . | N19: =IF(MID(O19,1,3)="CH.",$E19,"") | P19: =IF(MID(O19,1,3)="CH.",VALUE(MID(O19,4,2))+0,".") -> . | R19: =IF(MID(O19,1,6)="C.out.","C.in."&MID(O19,7,2),".") -> . | S19: =IF(MID(T19,1,3)="CH.",$E19,"") | U19: =IF(MID(T19,1,3)="CH.",VALUE(MID(T19,4,2))+48,".") -> .
A20: in | B20: hang.01 | D20: hs.25 | E20: Organ | F20: =">" -> > | G20: L.in.15 | H20: =IF(MID(J20,1,3)="CH.",$E20,"") -> Organ | J20: CH.15 | K20: =IF(MID(J20,1,3)="CH.",VALUE(MID(J20,4,2))+96,".") -> 111 | M20: =IF(MID(J20,1,6)="B.out.","B.in."&MID(J20,7,2),".") -> . | N20: =IF(MID(O20,1,3)="CH.",$E20,"") | P20: =IF(MID(O20,1,3)="CH.",VALUE(MID(O20,4,2))+0,".") -> . | R20: =IF(MID(O20,1,6)="C.out.","C.in."&MID(O20,7,2),".") -> . | S20: =IF(MID(T20,1,3)="CH.",$E20,"") | U20: =IF(MID(T20,1,3)="CH.",VALUE(MID(T20,4,2))+48,".") -> .
A21: in | B21: hang.03 | D21: hs.29 | E21: Room | F21: =">" -> > | G21: L.in.16 | H21: =IF(MID(J21,1,3)="CH.",$E21,"") -> Room | J21: CH.16 | K21: =IF(MID(J21,1,3)="CH.",VALUE(MID(J21,4,2))+96,".") -> 112 | M21: =IF(MID(J21,1,6)="B.out.","B.in."&MID(J21,7,2),".") -> . | N21: =IF(MID(O21,1,3)="CH.",$E21,"") | P21: =IF(MID(O21,1,3)="CH.",VALUE(MID(O21,4,2))+0,".") -> . | R21: =IF(MID(O21,1,6)="C.out.","C.in."&MID(O21,7,2),".") -> . | S21: =IF(MID(T21,1,3)="CH.",$E21,"") | U21: =IF(MID(T21,1,3)="CH.",VALUE(MID(T21,4,2))+48,".") -> .
A22: in | B22: SEN.11 | C22: sls.01 | D22: hs.18 | E22: Sing or Skit | F22: =">" -> > | G22: L.in.17 | H22: =IF(MID(J22,1,3)="CH.",$E22,"") | J22: B.out.01 | K22: =IF(MID(J22,1,3)="CH.",VALUE(MID(J22,4,2))+96,".") -> . | M22: =IF(MID(J22,1,6)="B.out.","B.in."&MID(J22,7,2),".") -> B.in.01 | N22: =IF(MID(O22,1,3)="CH.",$E22,"") -> Sing or Skit | O22: CH.18 | P22: =IF(MID(O22,1,3)="CH.",VALUE(MID(O22,4,2))+0,".") -> 18 | R22: =IF(MID(O22,1,6)="C.out.","C.in."&MID(O22,7,2),".") -> . | S22: =IF(MID(T22,1,3)="CH.",$E22,"") | U22: =IF(MID(T22,1,3)="CH.",VALUE(MID(T22,4,2))+48,".") -> .
A23: in | F23: =">" -> > | G23: L.in.18 | H23: =IF(MID(J23,1,3)="CH.",$E23,"") | K23: =IF(MID(J23,1,3)="CH.",VALUE(MID(J23,4,2))+96,".") -> . | M23: =IF(MID(J23,1,6)="B.out.","B.in."&MID(J23,7,2),".") -> . | N23: =IF(MID(O23,1,3)="CH.",$E23,"") | P23: =IF(MID(O23,1,3)="CH.",VALUE(MID(O23,4,2))+0,".") -> . | R23: =IF(MID(O23,1,6)="C.out.","C.in."&MID(O23,7,2),".") -> . | S23: =IF(MID(T23,1,3)="CH.",$E23,"") | U23: =IF(MID(T23,1,3)="CH.",VALUE(MID(T23,4,2))+48,".") -> .
A24: in | B24: SEN.12 | C24: sls.02 | D24: hs.31 | E24: Sing or Skit | F24: =">" -> > | G24: L.in.19 | H24: =IF(MID(J24,1,3)="CH.",$E24,"") | J24: B.out.02 | K24: =IF(MID(J24,1,3)="CH.",VALUE(MID(J24,4,2))+96,".") -> . | M24: =IF(MID(J24,1,6)="B.out.","B.in."&MID(J24,7,2),".") -> B.in.02 | N24: =IF(MID(O24,1,3)="CH.",$E24,"") -> Sing or Skit | O24: CH.19 | P24: =IF(MID(O24,1,3)="CH.",VALUE(MID(O24,4,2))+0,".") -> 19 | R24: =IF(MID(O24,1,6)="C.out.","C.in."&MID(O24,7,2),".") -> . | S24: =IF(MID(T24,1,3)="CH.",$E24,"") | U24: =IF(MID(T24,1,3)="CH.",VALUE(MID(T24,4,2))+48,".") -> .
A25: in | B25: SEN.06 | C25: sls.03 | D25: hs.32 | E25: SEN.06 | F25: =">" -> > | G25: L.in.20 | H25: =IF(MID(J25,1,3)="CH.",$E25,"") | J25: B.out.03 | K25: =IF(MID(J25,1,3)="CH.",VALUE(MID(J25,4,2))+96,".") -> . | M25: =IF(MID(J25,1,6)="B.out.","B.in."&MID(J25,7,2),".") -> B.in.03 | N25: =IF(MID(O25,1,3)="CH.",$E25,"") -> SEN.06 | O25: CH.20 | P25: =IF(MID(O25,1,3)="CH.",VALUE(MID(O25,4,2))+0,".") -> 20 | R25: =IF(MID(O25,1,6)="C.out.","C.in."&MID(O25,7,2),".") -> . | S25: =IF(MID(T25,1,3)="CH.",$E25,"") | U25: =IF(MID(T25,1,3)="CH.",VALUE(MID(T25,4,2))+48,".") -> .
A26: in | B26: SEN.07 | C26: sls.04 | D26: hs.33 | E26: SEN.07 | F26: =">" -> > | G26: L.in.21 | H26: =IF(MID(J26,1,3)="CH.",$E26,"") | J26: B.out.04 | K26: =IF(MID(J26,1,3)="CH.",VALUE(MID(J26,4,2))+96,".") -> . | M26: =IF(MID(J26,1,6)="B.out.","B.in."&MID(J26,7,2),".") -> B.in.04 | N26: =IF(MID(O26,1,3)="CH.",$E26,"") -> SEN.07 | O26: CH.21 | P26: =IF(MID(O26,1,3)="CH.",VALUE(MID(O26,4,2))+0,".") -> 21 | R26: =IF(MID(O26,1,6)="C.out.","C.in."&MID(O26,7,2),".") -> . | S26: =IF(MID(T26,1,3)="CH.",$E26,"") | U26: =IF(MID(T26,1,3)="CH.",VALUE(MID(T26,4,2))+48,".") -> .
A27: in | B27: SEN.08 | C27: sls.05 | D27: hs.34 | E27: SEN.08 | F27: =">" -> > | G27: L.in.22 | H27: =IF(MID(J27,1,3)="CH.",$E27,"") | J27: B.out.05 | K27: =IF(MID(J27,1,3)="CH.",VALUE(MID(J27,4,2))+96,".") -> . | M27: =IF(MID(J27,1,6)="B.out.","B.in."&MID(J27,7,2),".") -> B.in.05 | N27: =IF(MID(O27,1,3)="CH.",$E27,"") -> SEN.08 | O27: CH.22 | P27: =IF(MID(O27,1,3)="CH.",VALUE(MID(O27,4,2))+0,".") -> 22 | R27: =IF(MID(O27,1,6)="C.out.","C.in."&MID(O27,7,2),".") -> . | S27: =IF(MID(T27,1,3)="CH.",$E27,"") | U27: =IF(MID(T27,1,3)="CH.",VALUE(MID(T27,4,2))+48,".") -> .
A28: in | B28: SEN.09 | C28: sls.06 | D28: hs.35 | E28: SEN.09 | F28: =">" -> > | G28: L.in.23 | H28: =IF(MID(J28,1,3)="CH.",$E28,"") | J28: B.out.06 | K28: =IF(MID(J28,1,3)="CH.",VALUE(MID(J28,4,2))+96,".") -> . | M28: =IF(MID(J28,1,6)="B.out.","B.in."&MID(J28,7,2),".") -> B.in.06 | N28: =IF(MID(O28,1,3)="CH.",$E28,"") -> SEN.09 | O28: CH.23 | P28: =IF(MID(O28,1,3)="CH.",VALUE(MID(O28,4,2))+0,".") -> 23 | R28: =IF(MID(O28,1,6)="C.out.","C.in."&MID(O28,7,2),".") -> . | S28: =IF(MID(T28,1,3)="CH.",$E28,"") | U28: =IF(MID(T28,1,3)="CH.",VALUE(MID(T28,4,2))+48,".") -> .
A29: in | B29: SEN.10 | C29: sls.07 | D29: hs.36 | E29: SEN.10 | F29: =">" -> > | G29: L.in.24 | H29: =IF(MID(J29,1,3)="CH.",$E29,"") | J29: B.out.07 | K29: =IF(MID(J29,1,3)="CH.",VALUE(MID(J29,4,2))+96,".") -> . | M29: =IF(MID(J29,1,6)="B.out.","B.in."&MID(J29,7,2),".") -> B.in.07 | N29: =IF(MID(O29,1,3)="CH.",$E29,"") -> SEN.10 | O29: CH.24 | P29: =IF(MID(O29,1,3)="CH.",VALUE(MID(O29,4,2))+0,".") -> 24 | R29: =IF(MID(O29,1,6)="C.out.","C.in."&MID(O29,7,2),".") -> . | S29: =IF(MID(T29,1,3)="CH.",$E29,"") | U29: =IF(MID(T29,1,3)="CH.",VALUE(MID(T29,4,2))+48,".") -> .
A30: in | C30: sls.08 | D30: hs.09 | F30: =">" -> > | G30: L.in.25 | H30: =IF(MID(J30,1,3)="CH.",$E30,"") | K30: =IF(MID(J30,1,3)="CH.",VALUE(MID(J30,4,2))+96,".") -> . | M30: =IF(MID(J30,1,6)="B.out.","B.in."&MID(J30,7,2),".") -> . | N30: =IF(MID(O30,1,3)="CH.",$E30,"") | P30: =IF(MID(O30,1,3)="CH.",VALUE(MID(O30,4,2))+0,".") -> . | R30: =IF(MID(O30,1,6)="C.out.","C.in."&MID(O30,7,2),".") -> . | S30: =IF(MID(T30,1,3)="CH.",$E30,"") | U30: =IF(MID(T30,1,3)="CH.",VALUE(MID(T30,4,2))+48,".") -> .
A31: in | F31: =">" -> > | G31: L.in.26 | H31: =IF(MID(J31,1,3)="CH.",$E31,"") | K31: =IF(MID(J31,1,3)="CH.",VALUE(MID(J31,4,2))+96,".") -> . | M31: =IF(MID(J31,1,6)="B.out.","B.in."&MID(J31,7,2),".") -> . | N31: =IF(MID(O31,1,3)="CH.",$E31,"") | P31: =IF(MID(O31,1,3)="CH.",VALUE(MID(O31,4,2))+0,".") -> . | R31: =IF(MID(O31,1,6)="C.out.","C.in."&MID(O31,7,2),".") -> . | S31: =IF(MID(T31,1,3)="CH.",$E31,"") | U31: =IF(MID(T31,1,3)="CH.",VALUE(MID(T31,4,2))+48,".") -> .
A32: in | F32: =">" -> > | G32: L.in.27 | H32: =IF(MID(J32,1,3)="CH.",$E32,"") | K32: =IF(MID(J32,1,3)="CH.",VALUE(MID(J32,4,2))+96,".") -> . | M32: =IF(MID(J32,1,6)="B.out.","B.in."&MID(J32,7,2),".") -> . | N32: =IF(MID(O32,1,3)="CH.",$E32,"") | P32: =IF(MID(O32,1,3)="CH.",VALUE(MID(O32,4,2))+0,".") -> . | R32: =IF(MID(O32,1,6)="C.out.","C.in."&MID(O32,7,2),".") -> . | S32: =IF(MID(T32,1,3)="CH.",$E32,"") | U32: =IF(MID(T32,1,3)="CH.",VALUE(MID(T32,4,2))+48,".") -> .
A33: in | F33: =">" -> > | G33: L.in.28 | H33: =IF(MID(J33,1,3)="CH.",$E33,"") | K33: =IF(MID(J33,1,3)="CH.",VALUE(MID(J33,4,2))+96,".") -> . | M33: =IF(MID(J33,1,6)="B.out.","B.in."&MID(J33,7,2),".") -> . | N33: =IF(MID(O33,1,3)="CH.",$E33,"") | P33: =IF(MID(O33,1,3)="CH.",VALUE(MID(O33,4,2))+0,".") -> . | R33: =IF(MID(O33,1,6)="C.out.","C.in."&MID(O33,7,2),".") -> . | S33: =IF(MID(T33,1,3)="CH.",$E33,"") | U33: =IF(MID(T33,1,3)="CH.",VALUE(MID(T33,4,2))+48,".") -> .
A34: in | F34: =">" -> > | G34: L.in.29 | H34: =IF(MID(J34,1,3)="CH.",$E34,"") | K34: =IF(MID(J34,1,3)="CH.",VALUE(MID(J34,4,2))+96,".") -> . | M34: =IF(MID(J34,1,6)="B.out.","B.in."&MID(J34,7,2),".") -> . | N34: =IF(MID(O34,1,3)="CH.",$E34,"") | P34: =IF(MID(O34,1,3)="CH.",VALUE(MID(O34,4,2))+0,".") -> . | R34: =IF(MID(O34,1,6)="C.out.","C.in."&MID(O34,7,2),".") -> . | S34: =IF(MID(T34,1,3)="CH.",$E34,"") | U34: =IF(MID(T34,1,3)="CH.",VALUE(MID(T34,4,2))+48,".") -> .
A35: in | F35: =">" -> > | G35: L.in.30 | H35: =IF(MID(J35,1,3)="CH.",$E35,"") | K35: =IF(MID(J35,1,3)="CH.",VALUE(MID(J35,4,2))+96,".") -> . | M35: =IF(MID(J35,1,6)="B.out.","B.in."&MID(J35,7,2),".") -> . | N35: =IF(MID(O35,1,3)="CH.",$E35,"") | P35: =IF(MID(O35,1,3)="CH.",VALUE(MID(O35,4,2))+0,".") -> . | R35: =IF(MID(O35,1,6)="C.out.","C.in."&MID(O35,7,2),".") -> . | S35: =IF(MID(T35,1,3)="CH.",$E35,"") | U35: =IF(MID(T35,1,3)="CH.",VALUE(MID(T35,4,2))+48,".") -> .
A36: in | F36: =">" -> > | G36: L.in.31 | H36: =IF(MID(J36,1,3)="CH.",$E36,"") | K36: =IF(MID(J36,1,3)="CH.",VALUE(MID(J36,4,2))+96,".") -> . | M36: =IF(MID(J36,1,6)="B.out.","B.in."&MID(J36,7,2),".") -> . | N36: =IF(MID(O36,1,3)="CH.",$E36,"") | P36: =IF(MID(O36,1,3)="CH.",VALUE(MID(O36,4,2))+0,".") -> . | R36: =IF(MID(O36,1,6)="C.out.","C.in."&MID(O36,7,2),".") -> . | S36: =IF(MID(T36,1,3)="CH.",$E36,"") | U36: =IF(MID(T36,1,3)="CH.",VALUE(MID(T36,4,2))+48,".") -> .
A37: in | F37: =">" -> > | G37: L.in.32 | H37: =IF(MID(J37,1,3)="CH.",$E37,"") | K37: =IF(MID(J37,1,3)="CH.",VALUE(MID(J37,4,2))+96,".") -> . | M37: =IF(MID(J37,1,6)="B.out.","B.in."&MID(J37,7,2),".") -> . | N37: =IF(MID(O37,1,3)="CH.",$E37,"") | P37: =IF(MID(O37,1,3)="CH.",VALUE(MID(O37,4,2))+0,".") -> . | R37: =IF(MID(O37,1,6)="C.out.","C.in."&MID(O37,7,2),".") -> . | S37: =IF(MID(T37,1,3)="CH.",$E37,"") | U37: =IF(MID(T37,1,3)="CH.",VALUE(MID(T37,4,2))+48,".") -> .
A38: in | E38: BT-L | F38: =">" -> > | G38: aux.in.01 | H38: =IF(MID(J38,1,3)="CH.",$E38,"") -> BT-L | J38: CH.27 | K38: =IF(MID(J38,1,3)="CH.",VALUE(MID(J38,4,2))+96,".") -> 123 | M38: =IF(MID(J38,1,6)="B.out.","B.in."&MID(J38,7,2),".") -> . | N38: =IF(MID(O38,1,3)="CH.",$E38,"") | P38: =IF(MID(O38,1,3)="CH.",VALUE(MID(O38,4,2))+0,".") -> . | R38: =IF(MID(O38,1,6)="C.out.","C.in."&MID(O38,7,2),".") -> . | S38: =IF(MID(T38,1,3)="CH.",$E38,"") | U38: =IF(MID(T38,1,3)="CH.",VALUE(MID(T38,4,2))+48,".") -> .
A39: in | E39: BT-R | F39: =">" -> > | G39: aux.in.02 | H39: =IF(MID(J39,1,3)="CH.",$E39,"") -> BT-R | J39: CH.28 | K39: =IF(MID(J39,1,3)="CH.",VALUE(MID(J39,4,2))+96,".") -> 124 | M39: =IF(MID(J39,1,6)="B.out.","B.in."&MID(J39,7,2),".") -> . | N39: =IF(MID(O39,1,3)="CH.",$E39,"") | P39: =IF(MID(O39,1,3)="CH.",VALUE(MID(O39,4,2))+0,".") -> . | R39: =IF(MID(O39,1,6)="C.out.","C.in."&MID(O39,7,2),".") -> . | S39: =IF(MID(T39,1,3)="CH.",$E39,"") | U39: =IF(MID(T39,1,3)="CH.",VALUE(MID(T39,4,2))+48,".") -> .
A40: in | E40: CD-L | F40: =">" -> > | G40: aux.in.03 | H40: =IF(MID(J40,1,3)="CH.",$E40,"") -> CD-L | J40: CH.29 | K40: =IF(MID(J40,1,3)="CH.",VALUE(MID(J40,4,2))+96,".") -> 125 | M40: =IF(MID(J40,1,6)="B.out.","B.in."&MID(J40,7,2),".") -> . | N40: =IF(MID(O40,1,3)="CH.",$E40,"") | P40: =IF(MID(O40,1,3)="CH.",VALUE(MID(O40,4,2))+0,".") -> . | R40: =IF(MID(O40,1,6)="C.out.","C.in."&MID(O40,7,2),".") -> . | S40: =IF(MID(T40,1,3)="CH.",$E40,"") | U40: =IF(MID(T40,1,3)="CH.",VALUE(MID(T40,4,2))+48,".") -> .
...

Sheet By Chan
A1: BOARD SPOT | B1: GENERAL PLAN | D1: NAME | E1: START
A2: X1.CH.01 | B2: g1 Pr Jeff | C2: usrin.01 | D2: Pr Jeff | E2: =_xlfn.XLOOKUP($D2,REFS!$B$2:$B$187,REFS!$F$2:$F$187,"-") -> cmx.L.in.01
A3: X1.CH.02 | B3: g1 Vicar | C3: usrin.02 | D3: Vicar | E3: =_xlfn.XLOOKUP($D3,REFS!$B$2:$B$187,REFS!$F$2:$F$187,"-") -> cmx.L.in.02
A4: X1.CH.03 | B4: g1 Pr Paul | C4: usrin.03 | D4: Pr Paul | E4: =_xlfn.XLOOKUP($D4,REFS!$B$2:$B$187,REFS!$F$2:$F$187,"-") -> cmx.L.in.03
A5: X1.CH.04 | B5: g1 Kenzie | C5: usrin.04 | D5: Kenzie | E5: =_xlfn.XLOOKUP($D5,REFS!$B$2:$B$187,REFS!$F$2:$F$187,"-") -> cmx.L.in.04
A6: X1.CH.05 | B6: g1 Gst 1 | C6: usrin.05 | D6: Gst 1 | E6: =_xlfn.XLOOKUP($D6,REFS!$B$2:$B$187,REFS!$F$2:$F$187,"-") -> cmx.L.in.05
A7: X1.CH.06 | B7: g1 Gst 2 | C7: usrin.06 | D7: Gst 2 | E7: =_xlfn.XLOOKUP($D7,REFS!$B$2:$B$187,REFS!$F$2:$F$187,"-") -> cmx.L.in.06
A8: X1.CH.07 | B8: g1 Gst 3 | C8: usrin.07 | D8: Gst 3 | E8: =_xlfn.XLOOKUP($D8,REFS!$B$2:$B$187,REFS!$F$2:$F$187,"-") -> cmx.L.in.07
A9: X1.CH.08 | B9: g1 Altar HH | C9: usrin.08 | D9: Altar HH | E9: =_xlfn.XLOOKUP($D9,REFS!$B$2:$B$187,REFS!$F$2:$F$187,"-") -> cmx.L.in.11
A10: X1.CH.09 | C10: usrin.09 | D10: x | E10: =_xlfn.XLOOKUP($D10,REFS!$B$2:$B$187,REFS!$F$2:$F$187,"-") -> -
A11: X1.CH.10 | C11: usrin.10 | D11: x | E11: =_xlfn.XLOOKUP($D11,REFS!$B$2:$B$187,REFS!$F$2:$F$187,"-") -> -
A12: X1.CH.11 | C12: usrin.11 | D12: x | E12: =_xlfn.XLOOKUP($D12,REFS!$B$2:$B$187,REFS!$F$2:$F$187,"-") -> -
A13: X1.CH.12 | C13: usrin.12 | D13: x | E13: =_xlfn.XLOOKUP($D13,REFS!$B$2:$B$187,REFS!$F$2:$F$187,"-") -> -
A14: X1.CH.13 | C14: usrin.13 | D14: x | E14: =_xlfn.XLOOKUP($D14,REFS!$B$2:$B$187,REFS!$F$2:$F$187,"-") -> -
A15: X1.CH.14 | C15: usrin.14 | D15: x | E15: =_xlfn.XLOOKUP($D15,REFS!$B$2:$B$187,REFS!$F$2:$F$187,"-") -> -
A16: X1.CH.15 | B16: Organ | C16: usrin.15 | D16: Organ | E16: =_xlfn.XLOOKUP($D16,REFS!$B$2:$B$187,REFS!$F$2:$F$187,"-") -> cmx.L.in.15
A17: X1.CH.16 | B17: Room | C17: usrin.16 | D17: Room | E17: =_xlfn.XLOOKUP($D17,REFS!$B$2:$B$187,REFS!$F$2:$F$187,"-") -> cmx.L.in.16
A18: X1.CH.17 | B18: w1 Main in L | C18: usrin.17 | D18: x | E18: =_xlfn.XLOOKUP($D18,REFS!$B$2:$B$187,REFS!$F$2:$F$187,"-") -> -
A19: X1.CH.18 | B19: w1 Main in R | C19: usrin.18 | D19: x | E19: =_xlfn.XLOOKUP($D19,REFS!$B$2:$B$187,REFS!$F$2:$F$187,"-") -> -
A20: X1.CH.19 | B20: w1 Main in C | C20: usrin.19 | D20: x | E20: =_xlfn.XLOOKUP($D20,REFS!$B$2:$B$187,REFS!$F$2:$F$187,"-") -> -
A21: X1.CH.20 | B21: w1 Sub in | C21: usrin.20 | D21: x | E21: =_xlfn.XLOOKUP($D21,REFS!$B$2:$B$187,REFS!$F$2:$F$187,"-") -> -
A22: X1.CH.21 | B22: w1 M OvrChr in | C22: usrin.21 | D22: x | E22: =_xlfn.XLOOKUP($D22,REFS!$B$2:$B$187,REFS!$F$2:$F$187,"-") -> -
A23: X1.CH.22 | B23: w1 M Pno in | C23: usrin.22 | D23: x | E23: =_xlfn.XLOOKUP($D23,REFS!$B$2:$B$187,REFS!$F$2:$F$187,"-") -> -
A24: X1.CH.23 | B24: w1 M Org in | C24: usrin.23 | D24: x | E24: =_xlfn.XLOOKUP($D24,REFS!$B$2:$B$187,REFS!$F$2:$F$187,"-") -> -
A25: X1.CH.24 | B25: w1 M Gtr in | C25: usrin.24 | D25: x | E25: =_xlfn.XLOOKUP($D25,REFS!$B$2:$B$187,REFS!$F$2:$F$187,"-") -> -
A26: X1.CH.25 | B26: w1 M Vox in | C26: usrin.25 | D26: x | E26: =_xlfn.XLOOKUP($D26,REFS!$B$2:$B$187,REFS!$F$2:$F$187,"-") -> -
A27: X1.CH.26 | B27: w1 M Drum in | C27: usrin.26 | D27: x | E27: =_xlfn.XLOOKUP($D27,REFS!$B$2:$B$187,REFS!$F$2:$F$187,"-") -> -
A28: X1.CH.27 | C28: ="-" -> - | D28: x | E28: =_xlfn.XLOOKUP($D28,REFS!$B$2:$B$187,REFS!$F$2:$F$187,"-") -> -
A29: X1.CH.28 | C29: ="-" -> - | D29: x | E29: =_xlfn.XLOOKUP($D29,REFS!$B$2:$B$187,REFS!$F$2:$F$187,"-") -> -
A30: X1.CH.29 | C30: ="-" -> - | D30: x | E30: =_xlfn.XLOOKUP($D30,REFS!$B$2:$B$187,REFS!$F$2:$F$187,"-") -> -
A31: X1.CH.30 | C31: ="-" -> - | D31: x | E31: =_xlfn.XLOOKUP($D31,REFS!$B$2:$B$187,REFS!$F$2:$F$187,"-") -> -
A32: X1.CH.31 | C32: ="-" -> - | D32: x | E32: =_xlfn.XLOOKUP($D32,REFS!$B$2:$B$187,REFS!$F$2:$F$187,"-") -> -
A33: X1.CH.32 | C33: ="-" -> - | D33: x | E33: =_xlfn.XLOOKUP($D33,REFS!$B$2:$B$187,REFS!$F$2:$F$187,"-") -> -
A34: X1.Aux.1 | B34: BT-L (usrin.27) | C34: usrin.27 | D34: x | E34: =_xlfn.XLOOKUP($D34,REFS!$B$2:$B$187,REFS!$F$2:$F$187,"-") -> -
A35: X1.Aux.2 | B35: BT-R (usrin.28) | C35: usrin.28 | D35: x | E35: =_xlfn.XLOOKUP($D35,REFS!$B$2:$B$187,REFS!$F$2:$F$187,"-") -> -
A36: X1.Aux 3 | B36: CD-L (usrin.29) | C36: usrin.29 | D36: x | E36: =_xlfn.XLOOKUP($D36,REFS!$B$2:$B$187,REFS!$F$2:$F$187,"-") -> -
A37: X1.Aux.4 | B37: CD-R (usrin.30) | C37: usrin.30 | D37: x | E37: =_xlfn.XLOOKUP($D37,REFS!$B$2:$B$187,REFS!$F$2:$F$187,"-") -> -
A38: X1.Aux.5 | B38: PC-L (usrin.31) | C38: usrin.31 | D38: x | E38: =_xlfn.XLOOKUP($D38,REFS!$B$2:$B$187,REFS!$F$2:$F$187,"-") -> -
A39: X1.Aux.6 | B39: PC-R (usrin.32) | C39: usrin.32 | D39: x | E39: =_xlfn.XLOOKUP($D39,REFS!$B$2:$B$187,REFS!$F$2:$F$187,"-") -> -
A40: W1.CH.01 | B40: Group1 Spoken | D40: x | E40: =_xlfn.XLOOKUP($D40,REFS!$B$2:$B$187,REFS!$F$2:$F$187,"-") -> -
...
