Workbook

Sheet Settings
A1: Device | B1: Input | C1: Set Name | D1: SET Color Name | E1: mute | F1: mode | G1: icon | H1: pol | I1: vph | J1: name | K1: col
A2: WING1 | B2: LCL.1 | C2: Joeisacreepofallpeople | D2: Gold | E2: 0 | F2: M | G2: 14 | H2: 1 | I2: 0 | J2: =IF(C2="",SUBSTITUTE(B2, "/", "."),LEFT(C2,16)) -> Joeisacreepofall | K2: =IF(D2="",17,_xlfn.XLOOKUP(D2,refs!$A$2:$A$21,refs!$B$2:$B$21,"")) -> 13 | L2: ="PASSTHROUGH|"&A2&"^^/ s /io.in."&B2&".mute="&E2&",mode="&F2&",icon="&G2&",pol="&H2&",vph="&I2&",name="&J2&",col="&K2&"," -> PASSTHROUGH|WING1^^/ s /io.in.LCL.1.mute=0,mode=M,icon=14,pol=1,vph=0,name=Joeisacreepofall,col=13,
A3: WING1 | B3: LCL.2 | C3: sdfdf | D3: BrightB | E3: 0 | F3: ST | G3: 12 | H3: 0 | I3: 1 | J3: =IF(C3="",SUBSTITUTE(B3, "/", "."),LEFT(C3,16)) -> sdfdf | K3: =IF(D3="",17,_xlfn.XLOOKUP(D3,refs!$A$2:$A$21,refs!$B$2:$B$21,"")) -> 2 | L3: ="PASSTHROUGH|"&A3&"^^/ s /io.in."&B3&".mute="&E3&",mode="&F3&",icon="&G3&",pol="&H3&",vph="&I3&",name="&J3&",col="&K3&"," -> PASSTHROUGH|WING1^^/ s /io.in.LCL.2.mute=0,mode=ST,icon=12,pol=0,vph=1,name=sdfdf,col=2,
A4: WING1 | B4: LCL.3 | C4: joe | D4: BrightB | E4: 1 | F4: M/S | G4: 0 | H4: 0 | I4: 0 | J4: =IF(C4="",SUBSTITUTE(B4, "/", "."),LEFT(C4,16)) -> joe | K4: =IF(D4="",17,_xlfn.XLOOKUP(D4,refs!$A$2:$A$21,refs!$B$2:$B$21,"")) -> 2 | L4: ="PASSTHROUGH|"&A4&"^^/ s /io.in."&B4&".mute="&E4&",mode="&F4&",icon="&G4&",pol="&H4&",vph="&I4&",name="&J4&",col="&K4&"," -> PASSTHROUGH|WING1^^/ s /io.in.LCL.3.mute=1,mode=M/S,icon=0,pol=0,vph=0,name=joe,col=2,
A5: WING1 | B5: LCL.4 | C5: sam | D5: Violet | E5: 0 | F5: M | G5: 0 | H5: 0 | I5: 0 | J5: =IF(C5="",SUBSTITUTE(B5, "/", "."),LEFT(C5,16)) -> sam | K5: =IF(D5="",17,_xlfn.XLOOKUP(D5,refs!$A$2:$A$21,refs!$B$2:$B$21,"")) -> 3 | L5: ="PASSTHROUGH|"&A5&"^^/ s /io.in."&B5&".mute="&E5&",mode="&F5&",icon="&G5&",pol="&H5&",vph="&I5&",name="&J5&",col="&K5&"," -> PASSTHROUGH|WING1^^/ s /io.in.LCL.4.mute=0,mode=M,icon=0,pol=0,vph=0,name=sam,col=3,
A6: WING1 | B6: LCL.5 | C6: frank | D6: BrightB | E6: 0 | F6: M | G6: 0 | H6: 0 | I6: 0 | J6: =IF(C6="",SUBSTITUTE(B6, "/", "."),LEFT(C6,16)) -> frank | K6: =IF(D6="",17,_xlfn.XLOOKUP(D6,refs!$A$2:$A$21,refs!$B$2:$B$21,"")) -> 2 | L6: ="PASSTHROUGH|"&A6&"^^/ s /io.in."&B6&".mute="&E6&",mode="&F6&",icon="&G6&",pol="&H6&",vph="&I6&",name="&J6&",col="&K6&"," -> PASSTHROUGH|WING1^^/ s /io.in.LCL.5.mute=0,mode=M,icon=0,pol=0,vph=0,name=frank,col=2,
A7: WING1 | B7: LCL.6 | E7: 0 | F7: M | G7: 0 | H7: 0 | I7: 0 | J7: =IF(C7="",SUBSTITUTE(B7, "/", "."),LEFT(C7,16)) -> LCL.6 | K7: =IF(D7="",17,_xlfn.XLOOKUP(D7,refs!$A$2:$A$21,refs!$B$2:$B$21,"")) -> 17 | L7: ="PASSTHROUGH|"&A7&"^^/ s /io.in."&B7&".mute="&E7&",mode="&F7&",icon="&G7&",pol="&H7&",vph="&I7&",name="&J7&",col="&K7&"," -> PASSTHROUGH|WING1^^/ s /io.in.LCL.6.mute=0,mode=M,icon=0,pol=0,vph=0,name=LCL.6,col=17,
A8: WING1 | B8: LCL.7 | E8: 0 | F8: ST | G8: 0 | H8: 0 | I8: 0 | J8: =IF(C8="",SUBSTITUTE(B8, "/", "."),LEFT(C8,16)) -> LCL.7 | K8: =IF(D8="",17,_xlfn.XLOOKUP(D8,refs!$A$2:$A$21,refs!$B$2:$B$21,"")) -> 17 | L8: ="PASSTHROUGH|"&A8&"^^/ s /io.in."&B8&".mute="&E8&",mode="&F8&",icon="&G8&",pol="&H8&",vph="&I8&",name="&J8&",col="&K8&"," -> PASSTHROUGH|WING1^^/ s /io.in.LCL.7.mute=0,mode=ST,icon=0,pol=0,vph=0,name=LCL.7,col=17,
A9: WING1 | B9: LCL.8 | E9: 0 | F9: M | G9: 0 | H9: 0 | I9: 0 | J9: =IF(C9="",SUBSTITUTE(B9, "/", "."),LEFT(C9,16)) -> LCL.8 | K9: =IF(D9="",17,_xlfn.XLOOKUP(D9,refs!$A$2:$A$21,refs!$B$2:$B$21,"")) -> 17 | L9: ="PASSTHROUGH|"&A9&"^^/ s /io.in."&B9&".mute="&E9&",mode="&F9&",icon="&G9&",pol="&H9&",vph="&I9&",name="&J9&",col="&K9&"," -> PASSTHROUGH|WING1^^/ s /io.in.LCL.8.mute=0,mode=M,icon=0,pol=0,vph=0,name=LCL.8,col=17,
A10: WING1 | B10: LCL.9 | E10: 0 | F10: M/S | G10: 0 | H10: 0 | I10: 0 | J10: =IF(C10="",SUBSTITUTE(B10, "/", "."),LEFT(C10,16)) -> LCL.9 | K10: =IF(D10="",17,IF(C10="",17,_xlfn.XLOOKUP(D10,refs!$A$2:$A$21,refs!$B$2:$B$21,""))) -> 17 | L10: ="PASSTHROUGH|"&A10&"^^/ s /io.in."&B10&".mute="&E10&",mode="&F10&",icon="&G10&",pol="&H10&",vph="&I10&",name="&J10&",col="&K10&"," -> PASSTHROUGH|WING1^^/ s /io.in.LCL.9.mute=0,mode=M/S,icon=0,pol=0,vph=0,name=LCL.9,col=17,
A11: WING1 | B11: LCL.10 | E11: 0 | F11: M/S | G11: 0 | H11: 0 | I11: 0 | J11: =IF(C11="",SUBSTITUTE(B11, "/", "."),LEFT(C11,16)) -> LCL.10 | K11: =IF(D11="",17,IF(C11="",17,_xlfn.XLOOKUP(D11,refs!$A$2:$A$21,refs!$B$2:$B$21,""))) -> 17 | L11: ="PASSTHROUGH|"&A11&"^^/ s /io.in."&B11&".mute="&E11&",mode="&F11&",icon="&G11&",pol="&H11&",vph="&I11&",name="&J11&",col="&K11&"," -> PASSTHROUGH|WING1^^/ s /io.in.LCL.10.mute=0,mode=M/S,icon=0,pol=0,vph=0,name=LCL.10,col=17,
A12: WING1 | B12: LCL.11 | E12: 0 | F12: ST | G12: 0 | H12: 0 | I12: 0 | J12: =IF(C12="",SUBSTITUTE(B12, "/", "."),LEFT(C12,16)) -> LCL.11 | K12: =IF(D12="",17,IF(C12="",17,_xlfn.XLOOKUP(D12,refs!$A$2:$A$21,refs!$B$2:$B$21,""))) -> 17 | L12: ="PASSTHROUGH|"&A12&"^^/ s /io.in."&B12&".mute="&E12&",mode="&F12&",icon="&G12&",pol="&H12&",vph="&I12&",name="&J12&",col="&K12&"," -> PASSTHROUGH|WING1^^/ s /io.in.LCL.11.mute=0,mode=ST,icon=0,pol=0,vph=0,name=LCL.11,col=17,
A13: WING1 | B13: LCL.12 | E13: 0 | F13: ST | G13: 0 | H13: 0 | I13: 0 | J13: =IF(C13="",SUBSTITUTE(B13, "/", "."),LEFT(C13,16)) -> LCL.12 | K13: =IF(D13="",17,IF(C13="",17,_xlfn.XLOOKUP(D13,refs!$A$2:$A$21,refs!$B$2:$B$21,""))) -> 17 | L13: ="PASSTHROUGH|"&A13&"^^/ s /io.in."&B13&".mute="&E13&",mode="&F13&",icon="&G13&",pol="&H13&",vph="&I13&",name="&J13&",col="&K13&"," -> PASSTHROUGH|WING1^^/ s /io.in.LCL.12.mute=0,mode=ST,icon=0,pol=0,vph=0,name=LCL.12,col=17,
A14: WING1 | B14: LCL.13 | E14: 0 | F14: M | G14: 0 | H14: 0 | I14: 0 | J14: =IF(C14="",SUBSTITUTE(B14, "/", "."),LEFT(C14,16)) -> LCL.13 | K14: =IF(D14="",17,IF(C14="",17,_xlfn.XLOOKUP(D14,refs!$A$2:$A$21,refs!$B$2:$B$21,""))) -> 17 | L14: ="PASSTHROUGH|"&A14&"^^/ s /io.in."&B14&".mute="&E14&",mode="&F14&",icon="&G14&",pol="&H14&",vph="&I14&",name="&J14&",col="&K14&"," -> PASSTHROUGH|WING1^^/ s /io.in.LCL.13.mute=0,mode=M,icon=0,pol=0,vph=0,name=LCL.13,col=17,
A15: WING1 | B15: LCL.14 | E15: 0 | F15: M | G15: 0 | H15: 0 | I15: 0 | J15: =IF(C15="",SUBSTITUTE(B15, "/", "."),LEFT(C15,16)) -> LCL.14 | K15: =IF(D15="",17,IF(C15="",17,_xlfn.XLOOKUP(D15,refs!$A$2:$A$21,refs!$B$2:$B$21,""))) -> 17 | L15: ="PASSTHROUGH|"&A15&"^^/ s /io.in."&B15&".mute="&E15&",mode="&F15&",icon="&G15&",pol="&H15&",vph="&I15&",name="&J15&",col="&K15&"," -> PASSTHROUGH|WING1^^/ s /io.in.LCL.14.mute=0,mode=M,icon=0,pol=0,vph=0,name=LCL.14,col=17,
A16: WING1 | B16: LCL.15 | E16: 0 | F16: M | G16: 0 | H16: 0 | I16: 0 | J16: =IF(C16="",SUBSTITUTE(B16, "/", "."),LEFT(C16,16)) -> LCL.15 | K16: =IF(D16="",17,IF(C16="",17,_xlfn.XLOOKUP(D16,refs!$A$2:$A$21,refs!$B$2:$B$21,""))) -> 17 | L16: ="PASSTHROUGH|"&A16&"^^/ s /io.in."&B16&".mute="&E16&",mode="&F16&",icon="&G16&",pol="&H16&",vph="&I16&",name="&J16&",col="&K16&"," -> PASSTHROUGH|WING1^^/ s /io.in.LCL.15.mute=0,mode=M,icon=0,pol=0,vph=0,name=LCL.15,col=17,
A17: WING1 | B17: LCL.16 | E17: 0 | F17: M | G17: 0 | H17: 0 | I17: 0 | J17: =IF(C17="",SUBSTITUTE(B17, "/", "."),LEFT(C17,16)) -> LCL.16 | K17: =IF(D17="",17,IF(C17="",17,_xlfn.XLOOKUP(D17,refs!$A$2:$A$21,refs!$B$2:$B$21,""))) -> 17 | L17: ="PASSTHROUGH|"&A17&"^^/ s /io.in."&B17&".mute="&E17&",mode="&F17&",icon="&G17&",pol="&H17&",vph="&I17&",name="&J17&",col="&K17&"," -> PASSTHROUGH|WING1^^/ s /io.in.LCL.16.mute=0,mode=M,icon=0,pol=0,vph=0,name=LCL.16,col=17,
A18: WING1 | B18: LCL.17 | E18: 0 | F18: M | G18: 0 | H18: 0 | I18: 0 | J18: =IF(C18="",SUBSTITUTE(B18, "/", "."),LEFT(C18,16)) -> LCL.17 | K18: =IF(D18="",17,IF(C18="",17,_xlfn.XLOOKUP(D18,refs!$A$2:$A$21,refs!$B$2:$B$21,""))) -> 17 | L18: ="PASSTHROUGH|"&A18&"^^/ s /io.in."&B18&".mute="&E18&",mode="&F18&",icon="&G18&",pol="&H18&",vph="&I18&",name="&J18&",col="&K18&"," -> PASSTHROUGH|WING1^^/ s /io.in.LCL.17.mute=0,mode=M,icon=0,pol=0,vph=0,name=LCL.17,col=17,
A19: WING1 | B19: LCL.18 | E19: 0 | F19: M | G19: 0 | H19: 0 | I19: 0 | J19: =IF(C19="",SUBSTITUTE(B19, "/", "."),LEFT(C19,16)) -> LCL.18 | K19: =IF(D19="",17,IF(C19="",17,_xlfn.XLOOKUP(D19,refs!$A$2:$A$21,refs!$B$2:$B$21,""))) -> 17 | L19: ="PASSTHROUGH|"&A19&"^^/ s /io.in."&B19&".mute="&E19&",mode="&F19&",icon="&G19&",pol="&H19&",vph="&I19&",name="&J19&",col="&K19&"," -> PASSTHROUGH|WING1^^/ s /io.in.LCL.18.mute=0,mode=M,icon=0,pol=0,vph=0,name=LCL.18,col=17,
A20: WING1 | B20: LCL.19 | E20: 0 | F20: M | G20: 0 | H20: 0 | I20: 0 | J20: =IF(C20="",SUBSTITUTE(B20, "/", "."),LEFT(C20,16)) -> LCL.19 | K20: =IF(D20="",17,IF(C20="",17,_xlfn.XLOOKUP(D20,refs!$A$2:$A$21,refs!$B$2:$B$21,""))) -> 17 | L20: ="PASSTHROUGH|"&A20&"^^/ s /io.in."&B20&".mute="&E20&",mode="&F20&",icon="&G20&",pol="&H20&",vph="&I20&",name="&J20&",col="&K20&"," -> PASSTHROUGH|WING1^^/ s /io.in.LCL.19.mute=0,mode=M,icon=0,pol=0,vph=0,name=LCL.19,col=17,
A21: WING1 | B21: LCL.20 | E21: 0 | F21: M | G21: 0 | H21: 0 | I21: 0 | J21: =IF(C21="",SUBSTITUTE(B21, "/", "."),LEFT(C21,16)) -> LCL.20 | K21: =IF(D21="",17,IF(C21="",17,_xlfn.XLOOKUP(D21,refs!$A$2:$A$21,refs!$B$2:$B$21,""))) -> 17 | L21: ="PASSTHROUGH|"&A21&"^^/ s /io.in."&B21&".mute="&E21&",mode="&F21&",icon="&G21&",pol="&H21&",vph="&I21&",name="&J21&",col="&K21&"," -> PASSTHROUGH|WING1^^/ s /io.in.LCL.20.mute=0,mode=M,icon=0,pol=0,vph=0,name=LCL.20,col=17,
... A25: WING1 | B25: LCL.24 | E25: 0 | F25: M | G25: 0 | H25: 0 | I25: 0 | J25: =IF(C25="",SUBSTITUTE(B25, "/", "."),LEFT(C25,16)) -> LCL.24 | K25: =IF(D25="",17,IF(C25="",17,_xlfn.XLOOKUP(D25,refs!$A$2:$A$21,refs!$B$2:$B$21,""))) -> 17 | L25: ="PASSTHROUGH|"&A25&"^^/ s /io.in."&B25&".mute="&E25&",mode="&F25&",icon="&G25&",pol="&H25&",vph="&I25&",name="&J25&",col="&K25&"," -> PASSTHROUGH|WING1^^/ s /io.in.LCL.24.mute=0,mode=M,icon=0,pol=0,vph=0,name=LCL.24,col=17,
A26: WING1 | B26: AUX.1 | E26: 0 | F26: M | G26: 0 | H26: 0 | J26: =IF(C26="",SUBSTITUTE(B26, "/", "."),LEFT(C26,16)) -> AUX.1 | K26: =IF(D26="",17,IF(C26="",17,_xlfn.XLOOKUP(D26,refs!$A$2:$A$21,refs!$B$2:$B$21,""))) -> 17 | L26: ="PASSTHROUGH|"&A26&"^^/ s /io.in."&B26&".mute="&E26&",mode="&F26&",icon="&G26&",pol="&H26&",vph="&I26&",name="&J26&",col="&K26&"," -> PASSTHROUGH|WING1^^/ s /io.in.AUX.1.mute=0,mode=M,icon=0,pol=0,vph=,name=AUX.1,col=17,
A27: WING1 | B27: AUX.2 | E27: 0 | F27: M | G27: 0 | H27: 0 | J27: =IF(C27="",SUBSTITUTE(B27, "/", "."),LEFT(C27,16)) -> AUX.2 | K27: =IF(D27="",17,IF(C27="",17,_xlfn.XLOOKUP(D27,refs!$A$2:$A$21,refs!$B$2:$B$21,""))) -> 17 | L27: ="PASSTHROUGH|"&A27&"^^/ s /io.in."&B27&".mute="&E27&",mode="&F27&",icon="&G27&",pol="&H27&",vph="&I27&",name="&J27&",col="&K27&"," -> PASSTHROUGH|WING1^^/ s /io.in.AUX.2.mute=0,mode=M,icon=0,pol=0,vph=,name=AUX.2,col=17,
A28: WING1 | B28: AUX.3 | E28: 0 | F28: M | G28: 0 | H28: 0 | J28: =IF(C28="",SUBSTITUTE(B28, "/", "."),LEFT(C28,16)) -> AUX.3 | K28: =IF(D28="",17,IF(C28="",17,_xlfn.XLOOKUP(D28,refs!$A$2:$A$21,refs!$B$2:$B$21,""))) -> 17 | L28: ="PASSTHROUGH|"&A28&"^^/ s /io.in."&B28&".mute="&E28&",mode="&F28&",icon="&G28&",pol="&H28&",vph="&I28&",name="&J28&",col="&K28&"," -> PASSTHROUGH|WING1^^/ s /io.in.AUX.3.mute=0,mode=M,icon=0,pol=0,vph=,name=AUX.3,col=17,
A29: WING1 | B29: AUX.4 | E29: 0 | F29: M | G29: 0 | H29: 0 | J29: =IF(C29="",SUBSTITUTE(B29, "/", "."),LEFT(C29,16)) -> AUX.4 | K29: =IF(D29="",17,IF(C29="",17,_xlfn.XLOOKUP(D29,refs!$A$2:$A$21,refs!$B$2:$B$21,""))) -> 17 | L29: ="PASSTHROUGH|"&A29&"^^/ s /io.in."&B29&".mute="&E29&",mode="&F29&",icon="&G29&",pol="&H29&",vph="&I29&",name="&J29&",col="&K29&"," -> PASSTHROUGH|WING1^^/ s /io.in.AUX.4.mute=0,mode=M,icon=0,pol=0,vph=,name=AUX.4,col=17,
A30: WING1 | B30: AUX.5 | E30: 0 | F30: M | G30: 0 | H30: 0 | J30: =IF(C30="",SUBSTITUTE(B30, "/", "."),LEFT(C30,16)) -> AUX.5 | K30: =IF(D30="",17,IF(C30="",17,_xlfn.XLOOKUP(D30,refs!$A$2:$A$21,refs!$B$2:$B$21,""))) -> 17 | L30: ="PASSTHROUGH|"&A30&"^^/ s /io.in."&B30&".mute="&E30&",mode="&F30&",icon="&G30&",pol="&H30&",vph="&I30&",name="&J30&",col="&K30&"," -> PASSTHROUGH|WING1^^/ s /io.in.AUX.5.mute=0,mode=M,icon=0,pol=0,vph=,name=AUX.5,col=17,
A31: WING1 | B31: AUX.6 | E31: 0 | F31: M | G31: 0 | H31: 0 | J31: =IF(C31="",SUBSTITUTE(B31, "/", "."),LEFT(C31,16)) -> AUX.6 | K31: =IF(D31="",17,IF(C31="",17,_xlfn.XLOOKUP(D31,refs!$A$2:$A$21,refs!$B$2:$B$21,""))) -> 17 | L31: ="PASSTHROUGH|"&A31&"^^/ s /io.in."&B31&".mute="&E31&",mode="&F31&",icon="&G31&",pol="&H31&",vph="&I31&",name="&J31&",col="&K31&"," -> PASSTHROUGH|WING1^^/ s /io.in.AUX.6.mute=0,mode=M,icon=0,pol=0,vph=,name=AUX.6,col=17,
A32: WING1 | B32: AUX.7 | E32: 0 | F32: M | G32: 0 | H32: 0 | J32: =IF(C32="",SUBSTITUTE(B32, "/", "."),LEFT(C32,16)) -> AUX.7 | K32: =IF(D32="",17,IF(C32="",17,_xlfn.XLOOKUP(D32,refs!$A$2:$A$21,refs!$B$2:$B$21,""))) -> 17 | L32: ="PASSTHROUGH|"&A32&"^^/ s /io.in."&B32&".mute="&E32&",mode="&F32&",icon="&G32&",pol="&H32&",vph="&I32&",name="&J32&",col="&K32&"," -> PASSTHROUGH|WING1^^/ s /io.in.AUX.7.mute=0,mode=M,icon=0,pol=0,vph=,name=AUX.7,col=17,
A33: WING1 | B33: AUX.8 | E33: 0 | F33: M | G33: 0 | H33: 0 | J33: =IF(C33="",SUBSTITUTE(B33, "/", "."),LEFT(C33,16)) -> AUX.8 | K33: =IF(D33="",17,IF(C33="",17,_xlfn.XLOOKUP(D33,refs!$A$2:$A$21,refs!$B$2:$B$21,""))) -> 17 | L33: ="PASSTHROUGH|"&A33&"^^/ s /io.in."&B33&".mute="&E33&",mode="&F33&",icon="&G33&",pol="&H33&",vph="&I33&",name="&J33&",col="&K33&"," -> PASSTHROUGH|WING1^^/ s /io.in.AUX.8.mute=0,mode=M,icon=0,pol=0,vph=,name=AUX.8,col=17,
A34: WING1 | B34: A.1 | E34: 0 | F34: M | G34: 0 | H34: 0 | I34: 0 | J34: =IF(C34="",SUBSTITUTE(B34, "/", "."),LEFT(C34,16)) -> A.1 | K34: =IF(D34="",17,IF(C34="",17,_xlfn.XLOOKUP(D34,refs!$A$2:$A$21,refs!$B$2:$B$21,""))) -> 17 | L34: ="PASSTHROUGH|"&A34&"^^/ s /io.in."&B34&".mute="&E34&",mode="&F34&",icon="&G34&",pol="&H34&",vph="&I34&",name="&J34&",col="&K34&"," -> PASSTHROUGH|WING1^^/ s /io.in.A.1.mute=0,mode=M,icon=0,pol=0,vph=0,name=A.1,col=17,
A35: WING1 | B35: A.2 | E35: 0 | F35: M | G35: 0 | H35: 0 | I35: 0 | J35: =IF(C35="",SUBSTITUTE(B35, "/", "."),LEFT(C35,16)) -> A.2 | K35: =IF(D35="",17,IF(C35="",17,_xlfn.XLOOKUP(D35,refs!$A$2:$A$21,refs!$B$2:$B$21,""))) -> 17 | L35: ="PASSTHROUGH|"&A35&"^^/ s /io.in."&B35&".mute="&E35&",mode="&F35&",icon="&G35&",pol="&H35&",vph="&I35&",name="&J35&",col="&K35&"," -> PASSTHROUGH|WING1^^/ s /io.in.A.2.mute=0,mode=M,icon=0,pol=0,vph=0,name=A.2,col=17,
A36: WING1 | B36: A.3 | E36: 0 | F36: M | G36: 0 | H36: 0 | I36: 0 | J36: =IF(C36="",SUBSTITUTE(B36, "/", "."),LEFT(C36,16)) -> A.3 | K36: =IF(D36="",17,IF(C36="",17,_xlfn.XLOOKUP(D36,refs!$A$2:$A$21,refs!$B$2:$B$21,""))) -> 17 | L36: ="PASSTHROUGH|"&A36&"^^/ s /io.in."&B36&".mute="&E36&",mode="&F36&",icon="&G36&",pol="&H36&",vph="&I36&",name="&J36&",col="&K36&"," -> PASSTHROUGH|WING1^^/ s /io.in.A.3.mute=0,mode=M,icon=0,pol=0,vph=0,name=A.3,col=17,
A37: WING1 | B37: A.4 | E37: 0 | F37: M | G37: 0 | H37: 0 | I37: 0 | J37: =IF(C37="",SUBSTITUTE(B37, "/", "."),LEFT(C37,16)) -> A.4 | K37: =IF(D37="",17,IF(C37="",17,_xlfn.XLOOKUP(D37,refs!$A$2:$A$21,refs!$B$2:$B$21,""))) -> 17 | L37: ="PASSTHROUGH|"&A37&"^^/ s /io.in."&B37&".mute="&E37&",mode="&F37&",icon="&G37&",pol="&H37&",vph="&I37&",name="&J37&",col="&K37&"," -> PASSTHROUGH|WING1^^/ s /io.in.A.4.mute=0,mode=M,icon=0,pol=0,vph=0,name=A.4,col=17,
A38: WING1 | B38: A.5 | E38: 0 | F38: M | G38: 0 | H38: 0 | I38: 0 | J38: =IF(C38="",SUBSTITUTE(B38, "/", "."),LEFT(C38,16)) -> A.5 | K38: =IF(D38="",17,IF(C38="",17,_xlfn.XLOOKUP(D38,refs!$A$2:$A$21,refs!$B$2:$B$21,""))) -> 17 | L38: ="PASSTHROUGH|"&A38&"^^/ s /io.in."&B38&".mute="&E38&",mode="&F38&",icon="&G38&",pol="&H38&",vph="&I38&",name="&J38&",col="&K38&"," -> PASSTHROUGH|WING1^^/ s /io.in.A.5.mute=0,mode=M,icon=0,pol=0,vph=0,name=A.5,col=17,
A39: WING1 | B39: A.6 | E39: 0 | F39: M | G39: 0 | H39: 0 | I39: 0 | J39: =IF(C39="",SUBSTITUTE(B39, "/", "."),LEFT(C39,16)) -> A.6 | K39: =IF(D39="",17,IF(C39="",17,_xlfn.XLOOKUP(D39,refs!$A$2:$A$21,refs!$B$2:$B$21,""))) -> 17 | L39: ="PASSTHROUGH|"&A39&"^^/ s /io.in."&B39&".mute="&E39&",mode="&F39&",icon="&G39&",pol="&H39&",vph="&I39&",name="&J39&",col="&K39&"," -> PASSTHROUGH|WING1^^/ s /io.in.A.6.mute=0,mode=M,icon=0,pol=0,vph=0,name=A.6,col=17,
A40: WING1 | B40: A.7 | E40: 0 | F40: M | G40: 0 | H40: 0 | I40: 0 | J40: =IF(C40="",SUBSTITUTE(B40, "/", "."),LEFT(C40,16)) -> A.7 | K40: =IF(D40="",17,IF(C40="",17,_xlfn.XLOOKUP(D40,refs!$A$2:$A$21,refs!$B$2:$B$21,""))) -> 17 | L40: ="PASSTHROUGH|"&A40&"^^/ s /io.in."&B40&".mute="&E40&",mode="&F40&",icon="&G40&",pol="&H40&",vph="&I40&",name="&J40&",col="&K40&"," -> PASSTHROUGH|WING1^^/ s /io.in.A.7.mute=0,mode=M,icon=0,pol=0,vph=0,name=A.7,col=17,
A41: WING1 | B41: A.8 | E41: 0 | F41: M | G41: 0 | H41: 0 | I41: 0 | J41: =IF(C41="",SUBSTITUTE(B41, "/", "."),LEFT(C41,16)) -> A.8 | K41: =IF(D41="",17,IF(C41="",17,_xlfn.XLOOKUP(D41,refs!$A$2:$A$21,refs!$B$2:$B$21,""))) -> 17 | L41: ="PASSTHROUGH|"&A41&"^^/ s /io.in."&B41&".mute="&E41&",mode="&F41&",icon="&G41&",pol="&H41&",vph="&I41&",name="&J41&",col="&K41&"," -> PASSTHROUGH|WING1^^/ s /io.in.A.8.mute=0,mode=M,icon=0,pol=0,vph=0,name=A.8,col=17,
A42: WING1 | B42: A.9 | E42: 0 | F42: M | G42: 0 | H42: 0 | I42: 0 | J42: =IF(C42="",SUBSTITUTE(B42, "/", "."),LEFT(C42,16)) -> A.9 | K42: =IF(D42="",17,IF(C42="",17,_xlfn.XLOOKUP(D42,refs!$A$2:$A$21,refs!$B$2:$B$21,""))) -> 17 | L42: ="PASSTHROUGH|"&A42&"^^/ s /io.in."&B42&".mute="&E42&",mode="&F42&",icon="&G42&",pol="&H42&",vph="&I42&",name="&J42&",col="&K42&"," -> PASSTHROUGH|WING1^^/ s /io.in.A.9.mute=0,mode=M,icon=0,pol=0,vph=0,name=A.9,col=17,
A43: WING1 | B43: A.10 | E43: 0 | F43: M | G43: 0 | H43: 0 | I43: 0 | J43: =IF(C43="",SUBSTITUTE(B43, "/", "."),LEFT(C43,16)) -> A.10 | K43: =IF(D43="",17,IF(C43="",17,_xlfn.XLOOKUP(D43,refs!$A$2:$A$21,refs!$B$2:$B$21,""))) -> 17 | L43: ="PASSTHROUGH|"&A43&"^^/ s /io.in."&B43&".mute="&E43&",mode="&F43&",icon="&G43&",pol="&H43&",vph="&I43&",name="&J43&",col="&K43&"," -> PASSTHROUGH|WING1^^/ s /io.in.A.10.mute=0,mode=M,icon=0,pol=0,vph=0,name=A.10,col=17,
...

Sheet README
A1: Overview
A4: This script will build OSC commands to set the Name, Color, Mute, Mode, Icon, Polarity, and Phantom Power for each of the 448 WING inputs.
A5: Copy Column L into the clipboard and paste it into a Cue to use to enact these settings.
A7: Col A: Specify your DEVICE as used in the RUN and BUILD script device specifications
A8: Col B: This is prebuild for each input
A9: Col C: Place the name for the input here. Values can be:
B10: abcdefghijklmnopqrstuvwxyzABCDEFGHIJKLMNOPQRSTUVWXYZ1234567890.-_+
B11: Note that spaces are also not allowed. The first 16 characters of the name are passed to the WING.
A12: Col D: Set the desired color from the dropdown list
A13: Col E: Enter the OSC mute value (0 is no muted, 1 is muted)
A14: Col F: Enter the OSC mode value (M, ST, M/S)
A15: Col G: Enter the icon number to use (see the WING manual)
A16: Col H: Enter the Polarity (0 is normal, 1 is reversed)
A17: Col I: Enter the Phantom Power value (0 is off, 1 is on)
A18: Col J: This is filled by formula and has the first 16 characters of the name
A19: Col K: This is filled by formula and is the color number
A20: Col L: This is the cue content you should copy into a cue to run these settings.

Sheet Change Log
A1: 20261027a
A2: Initial Release

Sheet refs
A1: COLORS
A3: MediumB | B3: 1
A4: BrightB | B4: 2
A5: Violet | B5: 3
A6: Turquoise | B6: 4
A7: Green | B7: 5
A8: OliveG | B8: 6
A9: Yellow | B9: 7
A10: Brown | B10: 8
A11: Red | B11: 9
A12: Coral | B12: 10
A13: Pink | B13: 11
A14: DarkV | B14: 12
... A20: White | B20: 18
A24: MODES
A25: M
A26: ST
A27: M/S
